Workbook
Name オフィス: 注文書!#REF!
Name オフィス: 注文請書!#REF!
Name オフィス: 納品書!#REF!
Name オフィス: 検収書!#REF!
Name オフィス: '見積書4-表紙枚'!#REF!
Name オフィス: '見積書4-1枚'!#REF!
Name オフィス: '見積書4-2枚'!#REF!
Name オフィス: '見積書4-3枚'!#REF!

Sheet 固定マスタ
C1: 人事 | E1: 人事 | G1: 人事 | I1: 人事 | K1: 人事 | M1: 人事 | O1: 人事 | Q1: 人事 | S1: 人事 | U1: 人事 | W1: 人事 | Y1: 人事 | AA1: 人事 | AC1: 人事 | AE1: 人事 | AG1: 人事 | AI1: 人事 | AK1: 人事 | AM1: 人事 | AO1: 人事 | AQ1: 人事 | AS1: 人事 | AU1: 人事 | AW1: 人事 | AY1: 人事 | BA1: 人事 | BC1: 人事 | BE1: 人事 | BG1: 人事 | BI1: 計算用 | BK1: 計算用 | BM1: 計算用 | BO1: 計算用 | BQ1: 計算用 | BS1: 人事 | CG1: 共通 | CI1: 共通 | CK1: 共通 | CM1: 共通 | CO1: 共通 | CQ1: 共通 | CS1: 共通 | CU1: 共通 | CW1: 共通 | CY1: 共通 | DA1: 共通 | DC1: 共通 | DE1: 共通 | DG1: 共通 | DI1: 共通 | DK1: 共通 | EA1: 経理 | EC1: 経理 | EE1: 経理 | EG1: 経理 | EI1: 経理 | EY1: 委託 | FA1: 委託 | FC1: 委託 | FE1: 委託 | FG1: 委託 | FI1: 委託 | FK1: 委託 | FM1: 委託 | FO1: 委託 | FQ1: 委託 | FS1: 委託 | FU1: 委託 | FW1: 委託 | FY1: 委託 | GA1: 委託 | GC1: 委託 | GE1: 委託 | GG1: 委託 | GI1: 委託 | GK1: 委託 | GM1: 委託 | GO1: 委託 | HE1: 派遣 | HG1: 派遣 | HI1: 派遣 | HK1: 派遣 | HM1: 派遣 | HO1: 派遣 | HQ1: 派遣 | HS1: 派遣 | HU1: 派遣 | HW1: 派遣 | HY1: 派遣 | IA1: 派遣 | IC1: 派遣 | IE1: 派遣 | IG1: 派遣 | II1: 派遣 | IK1: 派遣 | IM1: 派遣 | IO1: 派遣 | IQ1: 派遣 | IS1: 派遣 | IU1: 派遣 | IW1: 派遣 | IY1: 派遣 | JA1: 派遣 | JC1: 派遣
A3: 更新日マスタ | C3: 名刺タイトルマスタ | E3: 部門マスタ1（上位所属） | F3: 正式名称 | G3: 部門マスタ2（部） | H3: 正式名称 | I3: 部門マスタ3（課） | J3: 正式名称 | K3: 部門マスタ4（グループ） | L3: 正式名称 | M3: 部門マスタ5（タスクフォース） | O3: 立経マスタ | Q3: 男女マスタ | S3: 国籍マスタ | U3: 賃金科目マスタ | W3: 賞与込マスタ | Y3: 雇用形態マスタ | AA3: コース概要マスタ | AC3: コース詳細マスタ | AE3: 考課階層マスタ | AG3: 雇用形態マスタ | AI3: 労働形態マスタ | AK3: 出向マスタ | AM3: 役職マスタ | AO3: コンサルタント役職マスタ | AQ3: スペシャリスト役職マスタ | AS3: 役割業績給 | AU3: 最低SP手当 | AW3: 役職手当 MSP手当 | AY3: 社員等級加工マスタ | BA3: 社員等級マスタ | BC3: 技術等級マスタ | BE3: 標準売上マスタ | BG3: 理論原価マスタ | BI3: 技術等級 | BK3: 標準売上（調整後） | BM3: 職位標準売上 | BO3: 職位標準売上上限 | BQ3: 職位標準売上下限 | BS3: 評価マスタ | CG3: 社名マスタ | CI3: 社名略称マスタ | CK3: エリアマスタ | CM3: 事業所マスタ | CO3: 住所マスタ | CQ3: 住所マスタ | CS3: 住所マスタ | CU3: ARI電話マスタ | CW3: ARIFAXマスタ | CY3: ATS電話マスタ | DA3: ATSFAXマスタ | DC3: ARI資格マスタ | DE3: ATS資格マスタ | DG3: 契約マスタ | DI3: 契約マスタ | DK3: 契約マスタ | EA3: 属性マスタ | EC3: 販管科目マスタ | EE3: 立経仕訳マスタ | EG3: 立経役職マスタ | EI3: 消費税マスタ | EY3: 契約マスタ | FA3: 契約マスタ | FC3: 契約マスタ | FE3: 契約マスタ | FG3: 契約マスタ | FI3: 契約マスタ | FK3: 契約マスタ | FM3: 契約マスタ | FO3: 契約マスタ | FQ3: 契約マスタ | FS3: 契約マスタ | FU3: 契約マスタ | FW3: 契約マスタ | FY3: 契約マスタ | GA3: 契約マスタ | GC3: 契約マスタ | GE3: 契約マスタ | GG3: 契約マスタ | GI3: 契約マスタ | GK3: 契約マスタ | GM3: 契約マスタ | GO3: 契約マスタ | HE3: 契約マスタ | HG3: 契約マスタ | HI3: 契約マスタ | HK3: 契約マスタ | HM3: 契約マスタ | HO3: 契約マスタ | HQ3: 契約マスタ | HS3: 契約マスタ | HU3: 契約マスタ | HW3: 契約マスタ | HY3: 契約マスタ | IA3: 契約マスタ | IC3: 契約マスタ | IE3: 契約マスタ | IG3: 契約マスタ | II3: 契約マスタ | IK3: 契約マスタ | IM3: 契約マスタ | IO3: 契約マスタ | IQ3: 契約マスタ | IS3: 契約マスタ | IU3: 契約マスタ | IW3: 契約マスタ | IY3: 契約マスタ | JA3: 契約マスタ | JC3: 契約マスタ
A4: 42948
C5: シニアアーキテクト | E5: 取締役会 | F5: グループ取締役会 | G5: 経営企画室 | H5: 経営企画室 | I5: WEB1課 | J5: WEBサービス開発第1課 | K5: 経企G | L5: 経営企画グループ | M5: 予備2 | O5: 取締役会 | Q5: 男性 | S5: 日本 | U5: 役割業績給 | W5: 賞与1/12 | Y5: 社員 | AA5: Eコース ： 技術・コンサルタント専門職務 | AC5: Eコース | AE5: 課長、担当課長、課長代理以上 | AG5: 経営・取締役 | AI5: 通常労働 | AK5: 通常在籍 | AM5: 代表付 | AO5: 予備2 | AQ5: 予備2 | AS5: 467000 | AW5: 170000 | AY5: =MID(BA5,1,1)&" "&MID(BA5,2,1)&" "&MID(BA5,3,LEN(BA5)) | BA5: 1-A | BC5: ITA1 | BE5: 4000000 | BG5: 2000000 | BI5: ITA1 | BK5: 4000000 | BM5: =AM5 | BO5: 0 | BQ5: 0 | BS5: A | CG5: ＡＲアドバンストテクノロジ株式会社 | CI5: ARI | CK5: 本社付 | CM5: 住所表示無 | DC5: 派遣番号 派13-308138 | DE5: 派遣番号 派13-305965 | DG5: 取引先(顧客) ⇒ 自社 | DI5: 代表取締役社長 | DK5: 武内 寿憲 | EA5: 原価 | EC5: 給与手当 | EE5: 旅費/駐車場 | EG5: ｱｼｽﾀﾝﾄﾘｰﾀﾞｰ | EI5: 計算しない | EY5: 個別契約書 | FA5: 注文書 | FC5: 注文請書 | FE5: 個別契約書 | FG5: 納品書 | FI5: 検収書 | FK5: 締結する | FM5: 御見積書 | FO5: 式 | FQ5: クライアント名 | FS5: 個別管理番号 | FU5: 作成日 | FW5: 項番 | FY5: ( \ ) | GA5: 御中 | GC5: 1 | GE5: Jan. | GG5: 出精お値引き | GI5: ※再委託書類 | GK5: ※上記金額は消費税を含みません | GM5: .00 | GO5: 代表者表示無 | HE5: 指揮命令者と同じ | HG5: 社員（常用社員） | HI5: 1 | HK5: 日 | HM5: 土曜日 | HO5: 10 | HQ5: 月額 | HS5: 月額精算 | HU5: 1日 | HW5: 毎月 | HY5: 当月 | IA5: 有 | IC5: 情報処理システム開発業務及び一体的に行われる付随業務 | IE5: 小数点切捨て | IG5: 派遣社員毎 | II5: 加入する | IK5: 加入済 | IM5: 但し、現在、必要書類の準備中であり、事後の届出予定 | IO5: 請求無 | IQ5: 有（定期券代を支給） | IS5: 加入要件有 | IU5: 18歳未満である | IW5: 派遣先の所定休日に準ずる | IY5: 別紙タイムカード（時間管理表･勤務表等）にて管理を行う | JA5: 無期雇用派遣労働者又は60歳以上の者に限定しない
C6: アプリケーションアーキテクト | E6: 監査役会 | F6: 監査役会 | G6: 経営管理部 | H6: 経営管理部 | I6: WEB2課 | J6: WEBサービス開発第2課 | K6: 教育G | L6: 教育グループ | M6: 予備3 | O6: 監査役会 | Q6: 女性 | S6: 日本(帰化) | U6: 役割残業給 | W6: 賞与2/12 | Y6: 社員（試用有） | AA6: Sコース ： 企画・営業専門職務 | AC6: EコースJSP(管理職級上級スペシャリスト) | AE6: スペシャリスト職 | AG6: 正社員 | AI6: 変形労働 | AK6: ARI出向 | AM6: 本社付 | AO6: 予備3 | AQ6: 予備3 | AS6: 457000 | AW6: 170000 | AY6: =MID(BA6,1,1)&" "&MID(BA6,2,1)&" "&MID(BA6,3,LEN(BA6)) | BA6: 1-B | BC6: ITA2 | BE6: 3500000 | BG6: 1950000 | BI6: ITA2 | BK6: 3500000 | BM6: =AM6 | BO6: 0 | BQ6: 0 | BS6: A- | CG6: 株式会社エーティーエス | CI6: ATS | CK6: 渋谷事業所 | CM6: 登記上本店(ARI) | CO6: 〒104-0032 | CQ6: 東京都中央区八丁堀1-14-8 | CS6: 丹羽ビル3F | CU6: TEL： 03-6450-6080 | CW6: FAX： 03-6450-6088 | DC6: 紹介番号 13-ユ-307154 | DE6: 紹介番号 13-ユ-307069 | DG6: 自社 ⇒ 取引先(BP) | DI6: CEO | DK6: 岡部 吉純 | EA6: 原価販管 | EC6: 役員報酬 | EE6: 旅費/電車代（ローカル線） | EG6: ﾘｰﾀﾞｰ | EI6: 0.01 | EY6: 仮個別契約書 | FA6: 仮注文書 | FC6: 仮注文請書 | FE6: 仮個別契約書 | FG6: 仮納品書 | FI6: 仮検収書 | FK6: 締結しない | FM6: 御見積書（概算） | FO6: 時間 | FQ6: パートナー名 | FS6: Code No | FU6: Date | FW6: NO. | FY6: (JPY) | GA6: To | GC6: 2 | GE6: Feb. | GG6: 右に記載⇒ | GI6: ※Subcontracted | GK6: ※上記金額は消費税を含みます | GM6: 予備3 | GO6: 代表者表示有 | HE6: 派遣先責任者と同じ | HG6: 個別契約社員・派遣登録社員 | HI6: 5 | HM6: 日曜日 | HO6: 15 | HQ6: 日額 | HS6: 月額固定 | HU6: 1日(平日) | HW6: 検収月 | HY6: 翌月 | IA6: 無 | IC6: 機械・設計業務及び一体的に行われる付随業務 | IE6: 小数点切上げ | IG6: 契約書毎 | II6: 加入しない | IK6: 加入要件有 | IM6: 短期の雇用で資格要件に達しない為 | IO6: 有（定期券代を請求） | IQ6: 有 | IS6: 加入要件外 | IU6: 45歳以上である | IW6: 予備3 | IY6: 予備3 | JA6: 無期雇用派遣労働者に限定する | JC6: 予備3
C7: データセンターアーキテクト | E7: 情報ｾｷｭﾘﾃｨ委員会 | F7: 情報セキュリティ委員会 | G7: 人事部 | H7: 人事部 | I7: WEB3課 | J7: WEBサービス開発第3課 | K7: 採用G | L7: 採用グループ | M7: 予備4 | O7: 委員会/ﾀｽｸﾌｫｰｽ | Q7: 予備4 | S7: 外国籍(中国在日) | U7: 基本給 | W7: 賞与3/12 | Y7: 社員（6ヶ月試用期間） | AA7: Cコース ： 管理・業務専門職務 | AC7: EコースMSP(管理職級スペシャリスト) | AE7: グループリーダー、リーダー、アシスタントリーダー職 | AG7: 契約社員 | AI7: 事業場外みなし | AK7: ATS出向 | AM7: 本部付 | AO7: 予備4 | AQ7: 予備4 | AS7: 447000 | AW7: 170000 | AY7: =MID(BA7,1,1)&" "&MID(BA7,2,1)&" "&MID(BA7,3,LEN(BA7)) | BA7: 1-C | BC7: ITA3 | BE7: 3000000 | BG7: 1800000 | BI7: ITA3 | BK7: 3000000 | BM7: =AM7 | BO7: 0 | BQ7: 0 | BS7: B+ | CG7: 株式会社ONE | CI7: ONE | CK7: 大阪事業所 | CM7: 渋谷本社 | CO7: 〒150-0002 | CQ7: 東京都渋谷区渋谷1-14-16 | CS7: 渋谷野村證券ビル8F | CU7: TEL： 03-6450-6080 | CW7: FAX： 03-6450-6088 | CY7: TEL： 03-6450-6084 | DA7: FAX： 03-6450-6085 | DC7: 全省庁統一資格 0000132746 | DE7: 予備4 | DG7: 予備4 | DI7: 予備4 | DK7: Toshinori.Takeuchi | EA7: 本社販管(営業) | EC7: 雑給 | EE7: 旅費/電車代（新幹線・特急） | EG7: ｸﾞﾙｰﾌﾟﾘｰﾀﾞｰ | EI7: 0.02 | EY7: 業務委託契約書 | FA7: Purchase Order | FC7: Order Confirmation | FE7: 業務委託契約書 | FG7: 予備4 | FI7: 予備4 | FK7: 予備4 | FM7: Quotation | FO7: 日 | FQ7: 予備4 | FS7: 予備4 | FU7: 予備4 | FW7: 品名 | FY7: (USD) | GA7: 予備4 | GC7: 3 | GE7: Mar. | GG7: 予備4 | GI7: 予備4 | GK7: ※本書のとおり注文いたします | GM7: 予備4 | GO7: 予備4 | HE7: 苦情担当者と同じ | HG7: 出向社員（グループ社員） | HI7: 6 | HK7: 月 | HM7: 祝日 | HO7: 20 | HQ7: 時間 | HS7: 時間精算 | HU7: 1月 | HW7: 四半期月 | HY7: 翌々月 | IA7: 手続き中 | IC7: 事務用機器操作業務及び一体的に行われる付随業務 | IE7: 小数点四捨五入 | IG7: 部署毎 | II7: 雇用保険のみ加入する | IK7: 加入要件外 | IM7: 予備4 | IO7: 有 | IQ7: 無 | IS7: 加入済 | IU7: 備考に入力 | IW7: 予備4 | IY7: 予備4 | JA7: 60歳以上の者に限定する | JC7: 予備4
C8: クラウドビジネスアーキテクト | E8: ｿﾘﾋﾞ本部 | F8: ソリューションビジネス本部 | G8: ｿﾘ営業部 | H8: ソリューション営業部 | I8: EP開1課 | J8: エンタープライズ開発第1課 | K8: 労務G | L8: 労務グループ | M8: 予備5 | O8: CPU | Q8: 予備5 | S8: 外国籍(中国就労) | U8: 調整給 | W8: 賞与4/12 | Y8: 契約社員（1ヶ月更新） | AA8: 予備5 | AC8: EコースLSP(リーダー職級スペシャリスト) | AE8: 一般職 | AG8: 個別契約社員 | AI8: 裁量労働 | AK8: その他出向 | AM8: 事業部付 | AO8: 予備5 | AQ8: 予備5 | AS8: 437000 | AW8: 170000 | AY8: =MID(BA8,1,1)&" "&MID(BA8,2,1)&" "&MID(BA8,3,LEN(BA8)) | BA8: 1-D | BC8: ITA4 | BE8: 2500000 | BG8: 1750000 | BI8: ITA3 | BK8: 3000000 | BM8: =AM8 | BO8: 0 | BQ8: 0 | BS8: B | CG8: AR advanced technology, Inc. | CI8: ARSG | CK8: 名古屋事業所 | CM8: 関西支社 | CO8: 〒530-0003 | CQ8: 大阪府大阪市北区堂島1-5-17 | CS8: 堂島グランドビル8F | CU8: TEL： 06-6136-4900 | CW8: FAX： 06-6136-4901 | CY8: TEL： 06-6136-4903 | DA8: FAX： 06-6136-4904 | DC8: プライバシーマーク取得認定番号 17000819（03） | DE8: 予備5 | DG8: 予備5 | DI8: 予備5 | DK8: Yoshizumi.Okabe | EA8: 本社販管(業務支援) | EC8: 賞与 | EE8: 旅費/航空代（国内） | EG8: 課長代理 | EI8: 0.03 | EY8: 覚書 | FA8: Preliminary Order | FC8: Preliminary Order Confirmation | FE8: 覚書 | FG8: 予備5 | FI8: 予備5 | FK8: 予備5 | FM8: Estimate | FO8: 週 | FQ8: 予備5 | FS8: 予備5 | FU8: 予備5 | FW8: DESCRIPTION | FY8: (SGD) | GA8: 予備5 | GC8: 4 | GE8: Apr. | GG8: 予備5 | GI8: 予備5 | GK8: ※本書のとおり注文をお請けします | GM8: 予備5 | GO8: 予備5 | HE8: 上記以外 | HG8: 予備5 | HI8: 10 | HM8: 土,日曜 | HO8: 25 | HQ8: 予備5 | HS8: 時間一律 | HU8: 予備5 | HW8: 予備5 | HY8: 予備5 | IA8: 予備5 | IC8: 通訳、翻訳、速記業務及び一体的に行われる付随業務 | IE8: 予備5 | IG8: 予備5 | II8: 予備5 | IK8: 予備5 | IM8: 予備5 | IO8: 予備5 | IQ8: 予備5 | IS8: 予備5 | IU8: 予備5 | IW8: 予備5 | IY8: 予備5 | JA8: 予備5 | JC8: 予備5
C9: アーキテクト | E9: ｺｰﾎﾟﾚｰﾄ本部 | F9: コーポレート本部 | G9: MCS部 | H9: ミッションクリティカルサービス部 | I9: EP開2課 | J9: エンタープライズ開発第2課 | K9: 庶務G | L9: 庶務グループ | M9: 予備6 | O9: NSU | Q9: 予備6 | S9: 外国籍(韓国在日) | U9: スペシャリスト手当 | W9: 賞与5/12 | Y9: 契約社員（3ヶ月更新） | AA9: 予備6 | AC9: Sコース | AE9: 予備6 | AG9: 個人（契約社員待遇者） | AI9: 予備6 | AK9: 社外出向 | AM9: 統括部付 | AO9: 予備6 | AQ9: 予備6 | AS9: 427000 | AW9: 170000 | AY9: =MID(BA9,1,1)&" "&MID(BA9,2,1)&" "&MID(BA9,3,LEN(BA9)) | BA9: 1-E | BC9: ITA5 | BE9: 2300000 | BG9: 1700000 | BI9: ITA3 | BK9: 3000000 | BM9: =AM9 | BO9: 0 | BQ9: 0 | BS9: B- | CG9: ATS, Inc. | CI9: ARID | CK9: 海外事業所 | CM9: 名古屋支社 | CO9: 〒450-0002 | CQ9: 愛知県名古屋市中村区名駅4-23-13 | CS9: 名古屋大同生命ビル3F | CU9: TEL： 052-446-8070 | CW9: FAX： 052-446-8071 | CY9: TEL： 052-446-8073 | DA9: FAX： 052-446-8074 | DC9: 予備6 | DE9: 予備6 | DG9: 予備6 | DI9: 予備6 | DK9: 予備6 | EA9: 本社販管(その他本社) | EC9: 退職金 | EE9: 旅費/航空代（海外） | EG9: 課長/PJ課長 | EI9: 0.04 | EY9: 予備6 | FA9: 予備6 | FC9: 予備6 | FE9: 予備6 | FG9: 予備6 | FI9: 予備6 | FK9: 予備6 | FM9: 予備6 | FO9: 月 | FQ9: 予備6 | FS9: 予備6 | FU9: 予備6 | FW9: 数量 | FY9: (THB) | GA9: 予備6 | GC9: 5 | GE9: May | GG9: 予備6 | GI9: 予備6 | GK9: ※見積有効期限は、本書日付後30日限りです | GM9: 予備6 | GO9: 予備6 | HG9: 予備6 | HI9: 15 | HK9: 火 | HM9: 日,祝日 | HO9: 30 | HQ9: 予備6 | HS9: 日額精算 | HU9: 予備6 | HW9: 予備6 | HY9: 予備6 | IA9: 予備6 | IC9: 調査業務及び一体的に行われる付随業務 | IE9: 予備6 | IG9: 予備6 | II9: 予備6 | IK9: 予備6 | IM9: 予備6 | IO9: 予備6 | IQ9: 予備6 | IS9: 予備6 | IU9: 予備6 | IW9: 予備6 | IY9: 予備6 | JA9: 予備6 | JC9: 予備6
E10: ｿﾘ営統括 | F10: ソリューション営業統括部 | G10: NBS部 | H10: ネットビジネスソリューション部 | I10: EP開3課 | J10: エンタープライズ開発第3課 | K10: 情ｼｽG | L10: 情報システムグループ | M10: 予備7 | O10: CSU | Q10: 予備7 | S10: 外国籍(韓国就労) | U10: リーダー職級SP手当 | W10: 賞与6/12 | Y10: 契約社員（6ヶ月更新） | AA10: 予備7 | AC10: SコースJSP(管理職級上級スペシャリスト) | AE10: 予備7 | AG10: 顧問 | AI10: 予備7 | AK10: 予備7 | AM10: ユニット付 | AO10: 予備7 | AQ10: 予備7 | AS10: 417000 | AW10: 170000 | AY10: =MID(BA10,1,1)&" "&MID(BA10,2,1)&" "&MID(BA10,3,LEN(BA10)) | BA10: 1-F | BC10: ITA6 | BE10: 2000000 | BG10: 1650000 | BI10: ITA4 | BK10: 2500000 | BM10: =AM10 | BO10: 0 | BQ10: 0 | BS10: C+ | CG10: ONE, Inc. | CI10: ARTH | CK10: 予備7 | CM10: シンガポールオフィス | CO10: Niwa Bldg. 3F, | CQ10: 1-14-8 Hacchobori chuo-ku Tokyo, | CS10: 104-0032,Japan | CU10: TEL： +81-3-6450-6080 | CW10: FAX： +81-3-6450-6088 | DC10: 予備7 | DE10: 予備7 | DG10: 予備7 | DI10: 予備7 | DK10: 予備7 | EA10: 予備7 | EC10: 退職金掛金 | EE10: 旅費/ﾀｸｼ- | EG10: 室長代行/補佐 | EI10: 0.05 | EY10: 予備7 | FA10: 予備7 | FC10: 予備7 | FE10: 予備7 | FG10: 予備7 | FI10: 予備7 | FK10: 予備7 | FM10: 予備7 | FO10: 人日 | FQ10: 予備7 | FS10: 予備7 | FU10: 予備7 | FW10: QTY | FY10: (IDR) | GA10: 予備7 | GC10: 6 | GE10: Jun. | GG10: 予備7 | GI10: 予備7 | GK10: 貴社、益々のご清栄のこととお慶び申し上げます | GM10: 予備7 | GO10: 予備7 | HE10: 就業場所と同じ | HG10: 予備7 | HI10: 20 | HM10: 土日祝 | HO10: 末 | HQ10: 予備7 | HS10: 予備7 | HU10: 予備7 | HW10: 予備7 | HY10: 予備7 | IA10: 予備7 | IC10: デモンストレーション業務及び一体的に行われる付随業務 | IE10: 予備7 | IG10: 予備7 | II10: 予備7 | IK10: 予備7 | IM10: 予備7 | IO10: 予備7 | IQ10: 予備7 | IS10: 予備7 | IU10: 予備7 | IW10: 予備7 | IY10: 予備7 | JA10: 予備7 | JC10: 予備7
C11: シニアコンサルタント | E11: MCS（本部付） | F11: ミッションクリティカルサービス部（ソリビ本部付） | G11: PJS部 | H11: プロジェクトソリューション部 | I11: ｺﾝｻﾙ1課 | J11: コンサルティングサービス第1課 | K11: 経管G | L11: 経営管理グループ | M11: 予備8 | O11: TSU | Q11: 予備8 | S11: 外国籍(北朝鮮在日) | U11: 管理職級SP手当 | W11: 賞与7/12 | Y11: 契約社員（12ヶ月/1年更新） | AA11: 予備8 | AC11: SコースMSP(管理職級スペシャリスト) | AE11: 予備8 | AG11: 外注(在籍出向社員) | AI11: 予備8 | AK11: 予備8 | AM11: 部付 | AO11: 予備8 | AQ11: 予備8 | AS11: 407000 | AW11: 155000 | AY11: =MID(BA11,1,1)&" "&MID(BA11,2,1)&" "&MID(BA11,3,LEN(BA11)) | BA11: 1-G | BC11: ITA7 | BE11: 1900000 | BG11: 1600000 | BI11: ITA4 | BK11: 2500000 | BM11: =AM11 | BO11: 0 | BQ11: 0 | BS11: C | CG11: Advanced Research Institute Pte.Ltd. | CI11: 予備8 | CK11: 予備8 | CM11: インドネシアオフィス | CO11: Shibuya Nomura Shoken Bldg. 8F, | CQ11: 1-14-16 Shibuya | CS11: Shibuya-ku Tokyo, 150-0002,Japan | CU11: TEL： +81-3-6450-6080 | CW11: FAX： +81-3-6450-6088 | CY11: TEL： +81-3-6450-6084 | DA11: FAX： +81-3-6450-6085 | DC11: 予備8 | DE11: 予備8 | DG11: 予備8 | DI11: 予備8 | DK11: 予備8 | EA11: 予備8 | EC11: 法定福利費 | EE11: 旅費/宿泊代 | EG11: 室長 | EI11: 0.06 | EY11: 予備8 | FA11: 予備8 | FC11: 予備8 | FE11: 予備8 | FG11: 予備8 | FI11: 予備8 | FK11: 予備8 | FM11: 予備8 | FO11: 人月 | FQ11: 予備8 | FS11: 予備8 | FU11: 予備8 | FW11: 単位 | FY11: 予備8 | GA11: 予備8 | GC11: 7 | GE11: Jul. | GG11: 予備8 | GI11: 予備8 | GK11: 下記のとおり納品いたしますのでご査収くださいますようお願い申し上げます | GM11: 予備8 | GO11: 予備8 | HE11: 上記以外 | HG11: 予備8 | HI11: 30 | HK11: 水 | HM11: 予備8 | HO11: 予備8 | HQ11: 予備8 | HS11: 予備8 | HU11: 予備8 | HW11: 予備8 | HY11: 予備8 | IA11: 予備8 | IC11: 研究開発業務及び一体的に行われる付随業務 | IE11: 予備8 | IG11: 予備8 | II11: 予備8 | IK11: 予備8 | IM11: 予備8 | IO11: 予備8 | IQ11: 予備8 | IS11: 予備8 | IU11: 予備8 | IW11: 予備8 | IY11: 予備8 | JA11: 予備8 | JC11: 予備8
C12: コンサルタント | E12: EPS統括 | F12: エンタープライズソリューション統括部 | G12: CON部 | H12: コンサルティングサービス部 | I12: ｺﾝｻﾙ2課 | J12: コンサルティングサービス第2課 | K12: ｱﾄﾞﾐG | L12: アドミニストレーショングループ | M12: 予備9 | O12: SSU | Q12: 予備9 | S12: 外国籍(北朝鮮就労) | U12: 役職手当 | W12: 賞与8/12 | Y12: 予備9 | AA12: 予備9 | AC12: SコースLSP(リーダー職級スペシャリスト) | AE12: 予備9 | AG12: 外注（BP） | AI12: 予備9 | AK12: 予備9 | AM12: 室付 | AO12: 予備9 | AQ12: 予備9 | AS12: 397000 | AW12: 155000 | AY12: =MID(BA12,1,1)&" "&MID(BA12,2,1)&" "&MID(BA12,3,LEN(BA12)) | BA12: 1-H | BC12: ITA8 | BE12: 1800000 | BG12: 1550000 | BI12: ITA4 | BK12: 2500000 | BM12: =AM12 | BO12: 0 | BQ12: 0 | BS12: C- | CG12: PT.Advanced Research Indonesia | CI12: 予備9 | CK12: 予備9 | CM12: タイオフィス | CO12: Dojima Grand Bldg. 8F, | CQ12: 1-5-17 Dojima | CS12: Kita-ku Osaka-shi Osaka, 530-0003, Japan | CU12: TEL： +81-6-6136-4900 | CW12: FAX： +81-6-6136-4901 | CY12: TEL： +81-6-6136-4903 | DA12: FAX： +81-6-6136-4904 | DC12: 予備9 | DE12: 予備9 | DG12: 予備9 | DI12: 予備9 | DK12: 予備9 | EA12: 予備9 | EC12: 福利厚生費 | EE12: 旅費/日当 ※課税 | EG12: 部長代行/補佐 | EI12: 0.07 | EY12: 予備9 | FA12: 予備9 | FC12: 予備9 | FE12: 予備9 | FG12: 予備9 | FI12: 予備9 | FK12: 予備9 | FM12: 予備9 | FO12: 個 | FQ12: 予備9 | FS12: 予備9 | FU12: 予備9 | FW12: UNIT | FY12: 予備9 | GA12: 予備9 | GC12: 8 | GE12: Aug. | GG12: 予備9 | GI12: 予備9 | GK12: 下記のとおり検収いたしますのでご査収くださいますようお願い申し上げます | GM12: 予備9 | GO12: 予備9 | HE12: 予備9 | HG12: 予備9 | HI12: 60 | HM12: 予備9 | HO12: 予備9 | HQ12: 予備9 | HS12: 予備9 | HU12: 予備9 | HW12: 予備9 | HY12: 予備9 | IA12: 予備9 | IC12: 事業の実施体制の企画、立案業務及び一体的に行われる付随業務 | IE12: 予備9 | IG12: 予備9 | II12: 予備9 | IK12: 予備9 | IM12: 予備9 | IO12: 予備9 | IQ12: 予備9 | IS12: 予備9 | IU12: 予備9 | IW12: 予備9 | IY12: 予備9 | JA12: 予備9 | JC12: 予備9
E13: PS統括 | F13: プロフェッショナルサービス統括部 | G13: AS部 | H13: アドバンストサービス部 | I13: AS1課 | J13: アドバンストサービス第1課 | K13: ﾌﾛﾝﾄG | L13: フロント支援グループ | M13: 予備10 | O13: PRS | Q13: 予備10 | S13: 外国籍(台湾在日) | U13: 機密情報取扱手当 | W13: 賞与9/12 | Y13: 予備10 | AA13: 予備10 | AC13: Cコース | AE13: 予備10 | AG13: 予備10 | AI13: 予備10 | AK13: 予備10 | AM13: 課付 | AO13: 予備10 | AQ13: 予備10 | AS13: 387000 | AW13: 155000 | AY13: =MID(BA13,1,1)&" "&MID(BA13,2,1)&" "&MID(BA13,3,LEN(BA13)) | BA13: 1-I | BC13: ITA9 | BE13: 1700000 | BG13: 1500000 | BI13: ITA5 | BK13: 2300000 | BM13: =AM13 | BO13: 0 | BQ13: 0 | BS13: D+ | CG13: ARMS (Thailand) Co., Ltd. | CI13: 予備10 | CK13: 予備10 | CM13: 予備10 | CO13: Nagoya Daido Seimei Bldg. 3F, | CQ13: 4-23-13 Meieki | CS13: Nakamura-ku Nagoya-shi Aichi, 530-0003, Japan | CU13: TEL： +81-52-446-8070 | CW13: FAX： +81-52-446-8071 | CY13: TEL： +81-52-446-8073 | DA13: FAX： +81-52-446-8074 | DC13: 予備10 | DE13: 予備10 | DG13: 予備10 | DI13: 予備10 | DK13: 予備10 | EA13: 予備10 | EC13: 通信費 | EE13: 旅費/その他 | EG13: 部長/PJ部長 | EI13: 0.08 | EY13: 予備10 | FA13: 予備10 | FC13: 予備10 | FE13: 予備10 | FG13: 予備10 | FI13: 予備10 | FK13: 予備10 | FM13: 予備10 | FO13: SET | FQ13: 予備10 | FS13: 予備10 | FU13: 予備10 | FW13: 単価 | FY13: 予備10 | GA13: 予備10 | GC13: 9 | GE13: Sep. | GG13: 予備10 | GI13: 予備10 | GK13: 予備10 | GM13: 予備10 | GO13: 予備10 | HE13: 予備10 | HG13: 予備10 | HI13: 予備10 | HK13: 木 | HM13: 予備10 | HO13: 予備10 | HQ13: 予備10 | HS13: 予備10 | HU13: 予備10 | HW13: 予備10 | HY13: 予備10 | IA13: 予備10 | IC13: 広告デザイン業務及び一体的に行われる付随業務 | IE13: 予備10 | IG13: 予備10 | II13: 予備10 | IK13: 予備10 | IM13: 予備10 | IO13: 予備10 | IQ13: 予備10 | IS13: 予備10 | IU13: 予備10 | IW13: 予備10 | IY13: 予備10 | JA13: 予備10 | JC13: 予備10
C14: シニアアソシエイト | E14: EB統括 | F14: エンタープライズビジネス統括部 | G14: ﾎﾞｲｽ部 | H14: ボイスサービス部 | I14: AS2課 | J14: アドバンストサービス第2課 | K14: 首都1G | L14: 首都圏第1グループ | M14: 予備11 | O14: 予備22 | Q14: 予備11 | S14: 外国籍(台湾就労) | U14: 通信手当 | W14: 賞与10/12 | Y14: 予備11 | AA14: 予備11 | AC14: CコースJSP(管理職級上級スペシャリスト) | AE14: 予備11 | AG14: 予備11 | AI14: 予備11 | AK14: 予備11 | AM14: 代表取締役社長 | AO14: 予備11 | AQ14: 予備11 | AS14: 377000 | AW14: 155000 | AY14: =MID(BA14,1,1)&" "&MID(BA14,2,1)&" "&MID(BA14,3,LEN(BA14)) | BA14: 1-J | BC14: ITA10 | BE14: 1600000 | BG14: 1450000 | BI14: ITA5 | BK14: 2300000 | BM14: =AM14 | BO14: 4000000 | BQ14: 2000000 | BS14: D | CG14: その他（社外） | CI14: 予備11 | CK14: 予備11 | CM14: 予備11 | CO14: Levels 30, Six Battery Road, | CS14: Singapore 049909 | CU14: 予備11 | CW14: 予備11 | CY14: 予備11 | DA14: 予備11 | DC14: 予備11 | DE14: 予備11 | DG14: 予備11 | DI14: 予備11 | DK14: 予備11 | EA14: 予備11 | EC14: 荷造運賃 | EE14: 飲食代/コミュニケーション費 | EG14: 統括部長代行/補佐 | EI14: 0.09 | EY14: 予備11 | FA14: 予備11 | FC14: 予備11 | FE14: 予備11 | FG14: 予備11 | FI14: 予備11 | FK14: 予備11 | FM14: 予備11 | FO14: HOUR | FQ14: 予備11 | FS14: 予備11 | FU14: 予備11 | FW14: UNIT PRICE | FY14: 予備11 | GA14: 予備11 | GC14: 10 | GE14: Oct. | GG14: 予備11 | GI14: 予備11 | GK14: 予備11 | GM14: 予備11 | GO14: 予備11 | HE14: 予備11 | HG14: 予備11 | HI14: 予備11 | HM14: 予備11 | HO14: 予備11 | HQ14: 予備11 | HS14: 予備11 | HU14: 予備11 | HW14: 予備11 | HY14: 予備11 | IA14: 予備11 | IC14: OAインストラクション業務及び一体的に行われる付随業務 | IE14: 予備11 | IG14: 予備11 | II14: 予備11 | IK14: 予備11 | IM14: 予備11 | IO14: 予備11 | IQ14: 予備11 | IS14: 予備11 | IU14: 予備11 | IW14: 予備11 | IY14: 予備11 | JA14: 予備11 | JC14: 予備11
C15: アソシエイト | E15: ｻﾋﾞ企（本部付） | F15: 新事業サービス企画室（ソリビ本部付） | G15: ﾈｯﾄﾜｰｸ部 | H15: ネットワークサービス部 | I15: BEX課 | J15: ブランドエクスペリエンス課 | K15: 首都2G | L15: 首都圏第2グループ | M15: 予備12 | O15: 予備23 | Q15: 予備12 | S15: 外国籍（その他在日） | U15: 住宅手当 | W15: 賞与11/12 | Y15: 予備12 | AA15: 予備12 | AC15: CコースMSP(管理職級スペシャリスト) | AE15: 予備12 | AG15: 予備12 | AI15: 予備12 | AK15: 予備12 | AM15: 代表取締役 | AO15: 予備12 | AQ15: 予備12 | AS15: 417000 | AW15: 140000 | AY15: =MID(BA15,1,1)&" "&MID(BA15,2,1)&" "&MID(BA15,3,LEN(BA15)) | BA15: 2-A | BC15: EE1 | BE15: 1500000 | BG15: 1400000 | BI15: ITA6 | BK15: 2000000 | BM15: =AM15 | BO15: 4000000 | BQ15: 2000000 | BS15: D- | CG15: 予備12 | CI15: 予備12 | CK15: 予備12 | CM15: 予備12 | CO15: Level 38, Tower A, | CQ15: Kota Kasablanka Jalan Casablanca | CS15: Raya Kav 88.Jakarta, 12870 Indonesia | CU15: 予備12 | CW15: 予備12 | CY15: 予備12 | DA15: 予備12 | DC15: 予備12 | DE15: 予備12 | DG15: 予備12 | DI15: 予備12 | DK15: 予備12 | EA15: 予備12 | EC15: 水道光熱費 | EE15: 飲食代/福利厚生費 | EG15: 統括部長 | EI15: 0.1 | EY15: 予備12 | FA15: 予備12 | FC15: 予備12 | FE15: 予備12 | FG15: 予備12 | FI15: 予備12 | FK15: 予備12 | FM15: 予備12 | FO15: DAY | FQ15: 予備12 | FS15: 予備12 | FU15: 予備12 | FW15: 金額 | FY15: 予備12 | GA15: 予備12 | GC15: 11 | GE15: Nov. | GG15: 予備12 | GI15: 予備12 | GK15: 予備12 | GM15: 予備12 | GO15: 予備12 | HE15: 予備12 | HG15: 予備12 | HI15: 予備12 | HK15: 金 | HM15: 予備12 | HO15: 予備12 | HQ15: 予備12 | HS15: 予備12 | HU15: 予備12 | HW15: 予備12 | HY15: 予備12 | IA15: 予備12 | IC15: セールスエンジニアの営業、金融商品の営業関係業務及び一体的に行われる付随業務 | IE15: 予備12 | IG15: 予備12 | II15: 予備12 | IK15: 予備12 | IM15: 予備12 | IO15: 予備12 | IQ15: 予備12 | IS15: 予備12 | IU15: 予備12 | IW15: 予備12 | IY15: 予備12 | JA15: 予備12 | JC15: 予備12
E16: 関西支社（本部付） | F16: 関西支社（ソリビ本部付） | G16: ｸﾗｳﾄﾞ部 | H16: クラウドビジネス部 | I16: C1課 | J16: コンサルティング第1課 | K16: 西ｾﾙG | L16: 西日本セールスグループ | M16: 予備13 | O16: 予備24 | Q16: 予備13 | S16: 外国籍（その他就労） | U16: 奨学金支援手当 | W16: 賞与12/12 | Y16: 予備13 | AA16: 予備13 | AC16: CコースLSP(リーダー職級スペシャリスト) | AE16: 予備13 | AG16: 予備13 | AI16: 予備13 | AK16: 予備13 | AM16: 専務取締役 | AO16: 予備13 | AQ16: 予備13 | AS16: 408000 | AW16: 140000 | AY16: =MID(BA16,1,1)&" "&MID(BA16,2,1)&" "&MID(BA16,3,LEN(BA16)) | BA16: 2-B | BC16: EE2 | BE16: 1400000 | BG16: 1350000 | BI16: ITA6 | BK16: 2000000 | BM16: =AM16 | BO16: 4000000 | BQ16: 2000000 | BS16: E+ | CG16: 予備13 | CI16: 予備13 | CK16: 予備13 | CM16: 予備13 | CO16: 10/188 The Trendy Office Building (25th floor), | CQ16: Sukhumvit Soi 13, | CS16: Klongtoey-Nua, Wattana, Bangkok 10110 Thailand | CU16: 予備13 | CW16: 予備13 | CY16: 予備13 | DA16: 予備13 | DC16: 予備13 | DE16: 予備13 | DG16: 予備13 | DI16: 予備13 | DK16: 予備13 | EA16: 予備13 | EC16: 旅費交通費 | EE16: 飲食代/会議費 | EG16: ユニット長代行/補佐 | EI16: 0.11 | EY16: 予備13 | FA16: 予備13 | FC16: 予備13 | FE16: 予備13 | FG16: 予備13 | FI16: 予備13 | FK16: 予備13 | FM16: 予備13 | FO16: WEEK | FQ16: 予備13 | FS16: 予備13 | FU16: 予備13 | FW16: AMOUNT | FY16: 予備13 | GA16: 予備13 | GC16: 12 | GE16: Dec. | GG16: 予備13 | GI16: 予備13 | GK16: 予備13 | GM16: 予備13 | GO16: 予備13 | HE16: 予備13 | HG16: 予備13 | HI16: 予備13 | HM16: 予備13 | HO16: 予備13 | HQ16: 予備13 | HS16: 予備13 | HU16: 予備13 | HW16: 予備13 | HY16: 予備13 | IA16: 予備13 | IC16: テレマーケティングの営業業務及び一体的に行われる付随業務 | IE16: 予備13 | IG16: 予備13 | II16: 予備13 | IK16: 予備13 | IM16: 予備13 | IO16: 予備13 | IQ16: 予備13 | IS16: 予備13 | IU16: 予備13 | IW16: 予備13 | IY16: 予備13 | JA16: 予備13 | JC16: 予備13
C17: チーフ | E17: TS事業部 | F17: TS事業部 | G17: CDS部 | H17: クラウドデータサービス部 | I17: C2課 | J17: コンサルティング第2課 | K17: SOG | L17: セキュアオペレーショングループ | M17: 予備14 | O17: 予備25 | Q17: 予備14 | S17: 予備14 | U17: インセンティブ保証 | W17: 予備14 | Y17: 予備14 | AA17: 予備14 | AC17: 予備14 | AE17: 予備14 | AG17: 予備14 | AI17: 予備14 | AK17: 予備14 | AM17: 常務取締役 | AO17: 予備14 | AQ17: 予備14 | AS17: 399000 | AW17: 140000 | AY17: =MID(BA17,1,1)&" "&MID(BA17,2,1)&" "&MID(BA17,3,LEN(BA17)) | BA17: 2-C | BC17: EE3 | BE17: 1300000 | BG17: 1300000 | BI17: ITA7 | BK17: 1900000 | BM17: =AM17 | BO17: 4000000 | BQ17: 2000000 | BS17: E | CG17: 予備14 | CI17: 予備14 | CK17: 予備14 | CM17: 予備14 | CO17: 予備14 | CQ17: 予備14 | CS17: 予備14 | CU17: 予備14 | CW17: 予備14 | CY17: 予備14 | DA17: 予備14 | DC17: 予備14 | DE17: 予備14 | DG17: 予備14 | DI17: 予備14 | DK17: 予備14 | EA17: 予備14 | EC17: 広告宣伝費 | EE17: 飲食代/接待交際費 | EG17: ユニット長 | EI17: 0.12 | EY17: 予備14 | FA17: 予備14 | FC17: 予備14 | FE17: 予備14 | FG17: 予備14 | FI17: 予備14 | FK17: 予備14 | FM17: 予備14 | FO17: MONTH | FQ17: 予備14 | FS17: 予備14 | FU17: 予備14 | FW17: 備考 | FY17: 予備14 | GA17: 予備14 | GC17: 予備14 | GE17: 予備14 | GG17: 予備14 | GI17: 予備14 | GK17: 予備14 | GM17: 予備14 | GO17: 予備14 | HE17: 予備14 | HG17: 予備14 | HI17: 予備14 | HK17: 土 | HM17: 予備14 | HO17: 予備14 | HQ17: 予備14 | HS17: 予備14 | HU17: 予備14 | HW17: 予備14 | HY17: 予備14 | IA17: 予備14 | IC17: 予備14 | IE17: 予備14 | IG17: 予備14 | II17: 予備14 | IK17: 予備14 | IM17: 予備14 | IO17: 予備14 | IQ17: 予備14 | IS17: 予備14 | IU17: 予備14 | IW17: 予備14 | IY17: 予備14 | JA17: 予備14 | JC17: 予備14
C18: チーフシステムエンジニア | E18: 代表付 | F18: 代表取締役社長付 | G18: ﾌﾟﾛｼﾞｪｸﾄ企画部 | H18: プロジェクトサービス企画部 | I18: C3課 | J18: コンサルティング第3課 | K18: TOG | L18: テクニカルオペレーショングループ | M18: 予備15 | O18: 予備26 | Q18: 予備15 | S18: 予備15 | U18: 決算インセンティブ | W18: 予備15 | Y18: 予備15 | AA18: 予備15 | AC18: 予備15 | AE18: 予備15 | AG18: 予備15 | AI18: 予備15 | AK18: 予備15 | AM18: 取締役 | AO18: 予備15 | AQ18: 予備15 | AS18: 390000 | AW18: 140000 | AY18: =MID(BA18,1,1)&" "&MID(BA18,2,1)&" "&MID(BA18,3,LEN(BA18)) | BA18: 2-D | BC18: EE4 | BE18: 1200000 | BG18: 1250000 | BI18: ITA8 | BK18: 1800000 | BM18: =AM18 | BO18: 4000000 | BQ18: 2000000 | BS18: EE4 | CG18: 予備15 | CI18: 予備15 | CK18: 予備15 | CM18: 予備15 | CO18: 予備15 | CQ18: 予備15 | CS18: 予備15 | CU18: 予備15 | CW18: 予備15 | CY18: 予備15 | DA18: 予備15 | DC18: 予備15 | DE18: 予備15 | DG18: 予備15 | DI18: 予備15 | DK18: 予備15 | EA18: 予備15 | EC18: 人材募集費 | EE18: 外注費 | EG18: 本部長代行/補佐 | EI18: 0.13 | EY18: 予備15 | FA18: 予備15 | FC18: 予備15 | FE18: 予備15 | FG18: 予備15 | FI18: 予備15 | FK18: 予備15 | FM18: 予備15 | FO18: 予備15 | FQ18: 予備15 | FS18: 予備15 | FU18: 予備15 | FW18: REMARK | FY18: 予備15 | GA18: 予備15 | GC18: 予備15 | GE18: 予備15 | GG18: 予備15 | GI18: 予備15 | GK18: 予備15 | GM18: 予備15 | GO18: 予備15 | HE18: 予備15 | HG18: 予備15 | HI18: 予備15 | HK18: 予備15 | HM18: 予備15 | HO18: 予備15 | HQ18: 予備15 | HS18: 予備15 | HU18: 予備15 | HW18: 予備15 | HY18: 予備15 | IA18: 予備15 | IC18: 予備15 | IE18: 予備15 | IG18: 予備15 | II18: 予備15 | IK18: 予備15 | IM18: 予備15 | IO18: 予備15 | IQ18: 予備15 | IS18: 予備15 | IU18: 予備15 | IW18: 予備15 | IY18: 予備15 | JA18: 予備15 | JC18: 予備15
C19: システムエンジニア | E19: TBU | F19: トップビジネスユニット | G19: EB部 | H19: エンタープライズビジネス部 | I19: C4課 | J19: コンサルティング第4課 | K19: BOG | L19: ビジネスオペレーショングループ | M19: 予備16 | O19: 予備27 | Q19: 予備16 | S19: 予備16 | U19: 会議手当 | W19: 予備16 | Y19: 予備16 | AA19: 予備16 | AC19: 予備16 | AE19: 予備16 | AG19: 予備16 | AI19: 予備16 | AK19: 予備16 | AM19: 取締役執行役員 | AO19: 予備16 | AQ19: 予備16 | AS19: 381000 | AW19: 140000 | AY19: =MID(BA19,1,1)&" "&MID(BA19,2,1)&" "&MID(BA19,3,LEN(BA19)) | BA19: 2-E | BC19: EE5 | BE19: 1100000 | BG19: 1200000 | BI19: ITA9 | BK19: 1700000 | BM19: =AM19 | BO19: 4000000 | BQ19: 2000000 | BS19: EE5 | CG19: 予備16 | CI19: 予備16 | CK19: 予備16 | CM19: 予備16 | CO19: 予備16 | CQ19: 予備16 | CS19: 予備16 | CU19: 予備16 | CW19: 予備16 | CY19: 予備16 | DA19: 予備16 | DC19: 予備16 | DE19: 予備16 | DG19: 予備16 | DI19: 予備16 | DK19: 予備16 | EA19: 予備16 | EC19: 採用教育費 | EE19: 荷造運賃 | EG19: 本部長 | EI19: 0.14 | EY19: 予備16 | FA19: 予備16 | FC19: 予備16 | FE19: 予備16 | FG19: 予備16 | FI19: 予備16 | FK19: 予備16 | FM19: 予備16 | FO19: 予備16 | FQ19: 予備16 | FS19: 予備16 | FU19: 予備16 | FW19: 通貨 | FY19: 予備16 | GA19: 予備16 | GC19: 予備16 | GE19: 予備16 | GG19: 予備16 | GI19: 予備16 | GK19: 予備16 | GM19: 予備16 | GO19: 予備16 | HE19: 予備16 | HG19: 予備16 | HI19: 予備16 | HK19: 予備16 | HM19: 予備16 | HO19: 予備16 | HQ19: 予備16 | HS19: 予備16 | HU19: 予備16 | HW19: 予備16 | HY19: 予備16 | IA19: 予備16 | IC19: 予備16 | IE19: 予備16 | IG19: 予備16 | II19: 予備16 | IK19: 予備16 | IM19: 予備16 | IO19: 予備16 | IQ19: 予備16 | IS19: 予備16 | IU19: 予備16 | IW19: 予備16 | IY19: 予備16 | JA19: 予備16 | JC19: 予備16
E20: TSU | F20: テクノロジーサービスユニット | G20: SI部 | H20: SIサービス部 | I20: C5課 | J20: コンサルティング第5課 | K20: COG | L20: カスタマーオペレーショングループ | M20: 予備17 | O20: 予備28 | Q20: 予備17 | S20: 予備17 | U20: プロジェクト給 | W20: 予備17 | Y20: 予備17 | AA20: 予備17 | AC20: 予備17 | AE20: 予備17 | AG20: 予備17 | AI20: 予備17 | AK20: 予備17 | AM20: 社外取締役 | AO20: 予備17 | AQ20: 予備17 | AS20: 372000 | AW20: 140000 | AY20: =MID(BA20,1,1)&" "&MID(BA20,2,1)&" "&MID(BA20,3,LEN(BA20)) | BA20: 2-F | BC20: EE6 | BE20: 1000000 | BG20: 1150000 | BI20: ITA9 | BK20: 1700000 | BM20: =AM20 | BO20: 4000000 | BQ20: 2000000 | BS20: EE6 | CG20: 予備17 | CI20: 予備17 | CK20: 予備17 | CM20: 予備17 | CO20: 予備17 | CQ20: 予備17 | CS20: 予備17 | CU20: 予備17 | CW20: 予備17 | CY20: 予備17 | DA20: 予備17 | DC20: 予備17 | DE20: 予備17 | DG20: 予備17 | DI20: 予備17 | DK20: 予備17 | EA20: 予備17 | EC20: コンサルタント料 | EE20: 広告宣伝費 | EG20: スペシャリスト | EI20: 0.15 | EY20: 予備17 | FA20: 予備17 | FC20: 予備17 | FE20: 予備17 | FG20: 予備17 | FI20: 予備17 | FK20: 予備17 | FM20: 予備17 | FO20: 予備17 | FQ20: 予備17 | FS20: 予備17 | FU20: 予備17 | FW20: C.U | FY20: 予備17 | GA20: 予備17 | GC20: 予備17 | GE20: 予備17 | GG20: 予備17 | GI20: 予備17 | GK20: 予備17 | GM20: 予備17 | GO20: 予備17 | HE20: 予備17 | HG20: 予備17 | HI20: 予備17 | HK20: 予備17 | HM20: 予備17 | HO20: 予備17 | HQ20: 予備17 | HS20: 予備17 | HU20: 予備17 | HW20: 予備17 | HY20: 予備17 | IA20: 予備17 | IC20: 予備17 | IE20: 予備17 | IG20: 予備17 | II20: 予備17 | IK20: 予備17 | IM20: 予備17 | IO20: 予備17 | IQ20: 予備17 | IS20: 予備17 | IU20: 予備17 | IW20: 予備17 | IY20: 予備17 | JA20: 予備17 | JC20: 予備17
C21: シニアプロジェクトマネージャ | E21: PRS | F21: プロフェッショナルリソースサービスユニット | G21: 関西 | H21: 関西支社 | I21: C6課 | J21: コンサルティング第6課 | K21: WEB1G | L21: WEB第1グループ | M21: 予備18 | O21: 予備29 | Q21: 予備18 | S21: 予備18 | U21: 予備18 | W21: 予備18 | Y21: 予備18 | AA21: 予備18 | AC21: 予備18 | AE21: 予備18 | AG21: 予備18 | AI21: 予備18 | AK21: 予備18 | AM21: 監査役 | AO21: 予備18 | AQ21: 予備18 | AS21: 363000 | AW21: 135000 | AY21: =MID(BA21,1,1)&" "&MID(BA21,2,1)&" "&MID(BA21,3,LEN(BA21)) | BA21: 2-G | BC21: EE7 | BE21: 950000 | BG21: 1100000 | BI21: ITA10 | BK21: 1600000 | BM21: =AM21 | BO21: 4000000 | BQ21: 2000000 | BS21: EE7 | CG21: 予備18 | CI21: 予備18 | CK21: 予備18 | CM21: 予備18 | CO21: 予備18 | CQ21: 予備18 | CS21: 予備18 | CU21: 予備18 | CW21: 予備18 | CY21: 予備18 | DA21: 予備18 | DC21: 予備18 | DE21: 予備18 | DG21: 予備18 | DI21: 予備18 | DK21: 予備18 | EA21: 予備18 | EC21: 接待交際費 | EE21: 採用教育費 | EG21: 上級スペシャリスト | EI21: 0.16 | EY21: 予備18 | FA21: 予備18 | FC21: 予備18 | FE21: 予備18 | FG21: 予備18 | FI21: 予備18 | FK21: 予備18 | FM21: 予備18 | FO21: 予備18 | FQ21: 予備18 | FS21: 予備18 | FU21: 予備18 | FW21: 小計 | FY21: 予備18 | GA21: 予備18 | GC21: 予備18 | GE21: 予備18 | GG21: 予備18 | GI21: 予備18 | GK21: 予備18 | GM21: 予備18 | GO21: 予備18 | HE21: 予備18 | HG21: 予備18 | HI21: 予備18 | HK21: 予備18 | HM21: 予備18 | HO21: 予備18 | HQ21: 予備18 | HS21: 予備18 | HU21: 予備18 | HW21: 予備18 | HY21: 予備18 | IA21: 予備18 | IC21: 予備18 | IE21: 予備18 | IG21: 予備18 | II21: 予備18 | IK21: 予備18 | IM21: 予備18 | IO21: 予備18 | IQ21: 予備18 | IS21: 予備18 | IU21: 予備18 | IW21: 予備18 | IY21: 予備18 | JA21: 予備18 | JC21: 予備18
C22: プロジェクトマネージャ | E22: CPU | F22: コーポレートユニット | G22: ｻﾋﾞ企 | H22: 新事業サービス企画室 | I22: C7課 | J22: コンサルティング第7課 | K22: WEB2G | L22: WEB第2グループ | M22: 予備19 | O22: 予備30 | Q22: 予備19 | S22: 予備19 | U22: 予備19 | W22: 予備19 | Y22: 予備19 | AA22: 予備19 | AC22: 予備19 | AE22: 予備19 | AG22: 予備19 | AI22: 予備19 | AK22: 予備19 | AM22: 社外監査役 | AO22: 予備19 | AQ22: 予備19 | AS22: 354000 | AW22: 135000 | AY22: =MID(BA22,1,1)&" "&MID(BA22,2,1)&" "&MID(BA22,3,LEN(BA22)) | BA22: 2-H | BC22: EE8 | BE22: 900000 | BG22: 1050000 | BI22: EE1 | BK22: 1500000 | BM22: =AM22 | BO22: 4000000 | BQ22: 2000000 | BS22: EE8 | CG22: 予備19 | CI22: 予備19 | CK22: 予備19 | CM22: 予備19 | CO22: 予備19 | CQ22: 予備19 | CS22: 予備19 | CU22: 予備19 | CW22: 予備19 | CY22: 予備19 | DA22: 予備19 | DC22: 予備19 | DE22: 予備19 | DG22: 予備19 | DI22: 予備19 | DK22: 予備19 | EA22: 予備19 | EC22: 会議費 | EE22: 通信費 | EG22: プリンシパル | EI22: 0.17 | EY22: 予備19 | FA22: 予備19 | FC22: 予備19 | FE22: 予備19 | FG22: 予備19 | FI22: 予備19 | FK22: 予備19 | FM22: 予備19 | FO22: 予備19 | FQ22: 予備19 | FS22: 予備19 | FU22: 予備19 | FW22: SUB TOTAL | FY22: 予備19 | GA22: 予備19 | GC22: 予備19 | GE22: 予備19 | GG22: 予備19 | GI22: 予備19 | GK22: 予備19 | GM22: 予備19 | GO22: 予備19 | HE22: 予備19 | HG22: 予備19 | HI22: 予備19 | HK22: 予備19 | HM22: 予備19 | HO22: 予備19 | HQ22: 予備19 | HS22: 予備19 | HU22: 予備19 | HW22: 予備19 | HY22: 予備19 | IA22: 予備19 | IC22: 予備19 | IE22: 予備19 | IG22: 予備19 | II22: 予備19 | IK22: 予備19 | IM22: 予備19 | IO22: 予備19 | IQ22: 予備19 | IS22: 予備19 | IU22: 予備19 | IW22: 予備19 | IY22: 予備19 | JA22: 予備19 | JC22: 予備19
E23: TDU | F23: タクティカルデザインユニット | G23: TS営業部 | H23: テクノロジーサービス営業部 | I23: C8課 | J23: コンサルティング第8課 | K23: WEB3G | L23: WEB第3グループ | M23: 予備20 | O23: 予備31 | Q23: 予備20 | S23: 予備20 | U23: 予備20 | W23: 予備20 | Y23: 予備20 | AA23: 予備20 | AC23: 予備20 | AE23: 予備20 | AG23: 予備20 | AI23: 予備20 | AK23: 予備20 | AM23: 担当執行役員 | AO23: 予備20 | AQ23: 予備20 | AS23: 345000 | AW23: 135000 | AY23: =MID(BA23,1,1)&" "&MID(BA23,2,1)&" "&MID(BA23,3,LEN(BA23)) | BA23: 2-I | BC23: EE9 | BE23: 850000 | BG23: 1000000 | BI23: EE2 | BK23: 1400000 | BM23: =AM23 | BO23: 4000000 | BQ23: 2000000 | BS23: EE9 | CG23: 予備20 | CI23: 予備20 | CK23: 予備20 | CM23: 予備20 | CO23: 予備20 | CQ23: 予備20 | CS23: 予備20 | CU23: 予備20 | CW23: 予備20 | CY23: 予備20 | DA23: 予備20 | DC23: 予備20 | DE23: 予備20 | DG23: 予備20 | DI23: 予備20 | DK23: 予備20 | EA23: 予備20 | EC23: 研修費 | EE23: 研修費 | EG23: 取締役 | EI23: 0.18 | EY23: 予備20 | FA23: 予備20 | FC23: 予備20 | FE23: 予備20 | FG23: 予備20 | FI23: 予備20 | FK23: 予備20 | FM23: 予備20 | FO23: 予備20 | FQ23: 予備20 | FS23: 予備20 | FU23: 予備20 | FW23: 合計 | FY23: 予備20 | GA23: 予備20 | GC23: 予備20 | GE23: 予備20 | GG23: 予備20 | GI23: 予備20 | GK23: 予備20 | GM23: 予備20 | GO23: 予備20 | HE23: 予備20 | HG23: 予備20 | HI23: 予備20 | HK23: 予備20 | HM23: 予備20 | HO23: 予備20 | HQ23: 予備20 | HS23: 予備20 | HU23: 予備20 | HW23: 予備20 | HY23: 予備20 | IA23: 予備20 | IC23: 予備20 | IE23: 予備20 | IG23: 予備20 | II23: 予備20 | IK23: 予備20 | IM23: 予備20 | IO23: 予備20 | IQ23: 予備20 | IS23: 予備20 | IU23: 予備20 | IW23: 予備20 | IY23: 予備20 | JA23: 予備20 | JC23: 予備20
C24: コンサルティングマネージャ | E24: SSU | F24: ソリューションセールスユニット | G24: PS | H24: プリンシパルセールス | I24: C9課 | J24: コンサルティング第9課 | K24: EP開1G | L24: EP開発第1グループ | M24: 予備21 | O24: 予備32 | Q24: 予備21 | S24: 予備21 | U24: 予備21 | W24: 予備21 | Y24: 予備21 | AA24: 予備21 | AC24: 予備21 | AE24: 予備21 | AG24: 予備21 | AI24: 予備21 | AK24: 予備21 | AM24: 本部長 | AO24: 予備21 | AQ24: 予備21 | AS24: 336000 | AW24: 135000 | AY24: =MID(BA24,1,1)&" "&MID(BA24,2,1)&" "&MID(BA24,3,LEN(BA24)) | BA24: 2-J | BC24: EE10 | BE24: 800000 | BG24: 980000 | BI24: EE2 | BK24: 1400000 | BM24: =AM24 | BO24: 4000000 | BQ24: 2000000 | BS24: EE10 | CG24: 予備21 | CI24: 予備21 | CK24: 予備21 | CM24: 予備21 | CO24: 予備21 | CQ24: 予備21 | CS24: 予備21 | CU24: 予備21 | CW24: 予備21 | CY24: 予備21 | DA24: 予備21 | DC24: 予備21 | DE24: 予備21 | DG24: 予備21 | DI24: 予備21 | DK24: 予備21 | EA24: 予備21 | EC24: 事務消耗品 | EE24: 備品消耗品費 | EG24: 予備21 | EI24: 0.19 | EY24: 予備21 | FA24: 予備21 | FC24: 予備21 | FE24: 予備21 | FG24: 予備21 | FI24: 予備21 | FK24: 予備21 | FM24: 予備21 | FO24: 予備21 | FQ24: 予備21 | FS24: 予備21 | FU24: 予備21 | FW24: TOTAL | FY24: 予備21 | GA24: 予備21 | GC24: 予備21 | GE24: 予備21 | GG24: 予備21 | GI24: 予備21 | GK24: 予備21 | GM24: 予備21 | GO24: 予備21 | HE24: 予備21 | HG24: 予備21 | HI24: 予備21 | HK24: 予備21 | HM24: 予備21 | HO24: 予備21 | HQ24: 予備21 | HS24: 予備21 | HU24: 予備21 | HW24: 予備21 | HY24: 予備21 | IA24: 予備21 | IC24: 予備21 | IE24: 予備21 | IG24: 予備21 | II24: 予備21 | IK24: 予備21 | IM24: 予備21 | IO24: 予備21 | IQ24: 予備21 | IS24: 予備21 | IU24: 予備21 | IW24: 予備21 | IY24: 予備21 | JA24: 予備21 | JC24: 予備21
C25: プロダクトマネージャ | E25: 予備22 | G25: 海外部 | H25: 海外法人部 | I25: C10課 | J25: コンサルティング第10課 | K25: EP開2G | L25: EP開発第2グループ | M25: 予備22 | O25: 予備33 | Q25: 予備22 | S25: 予備22 | U25: 予備22 | W25: 予備22 | Y25: 予備22 | AA25: 予備22 | AC25: 予備22 | AE25: 予備22 | AG25: 予備22 | AI25: 予備22 | AK25: 予備22 | AM25: 本部長代行 | AO25: 予備22 | AQ25: 予備22 | AS25: 372000 | AW25: 120000 | AY25: =MID(BA25,1,1)&" "&MID(BA25,2,1)&" "&MID(BA25,3,LEN(BA25)) | BA25: 3-A | BC25: EE11 | BE25: 750000 | BG25: 950000 | BI25: EE2 | BK25: 1400000 | BM25: =AM25 | BO25: 4000000 | BQ25: 2000000 | BS25: EE11 | CG25: 予備22 | CI25: 予備22 | CK25: 予備22 | CM25: 予備22 | CO25: 予備22 | CQ25: 予備22 | CS25: 予備22 | CU25: 予備22 | CW25: 予備22 | CY25: 予備22 | DA25: 予備22 | DC25: 予備22 | DE25: 予備22 | DG25: 予備22 | DI25: 予備22 | DK25: 予備22 | EA25: 予備22 | EC25: 事務用品 | EE25: 新聞図書費 | EG25: 予備22 | EI25: 0.2 | EY25: 予備22 | FA25: 予備22 | FC25: 予備22 | FE25: 予備22 | FG25: 予備22 | FI25: 予備22 | FK25: 予備22 | FM25: 予備22 | FO25: 予備22 | FQ25: 予備22 | FS25: 予備22 | FU25: 予備22 | FW25: 請求日付 | FY25: 予備22 | GA25: 予備22 | GC25: 予備22 | GE25: 予備22 | GG25: 予備22 | GI25: 予備22 | GK25: 予備22 | GM25: 予備22 | GO25: 予備22 | HE25: 予備22 | HG25: 予備22 | HI25: 予備22 | HK25: 予備22 | HM25: 予備22 | HO25: 予備22 | HQ25: 予備22 | HS25: 予備22 | HU25: 予備22 | HW25: 予備22 | HY25: 予備22 | IA25: 予備22 | IC25: 予備22 | IE25: 予備22 | IG25: 予備22 | II25: 予備22 | IK25: 予備22 | IM25: 予備22 | IO25: 予備22 | IQ25: 予備22 | IS25: 予備22 | IU25: 予備22 | IW25: 予備22 | IY25: 予備22 | JA25: 予備22 | JC25: 予備22
C26: テクニカルマネージャ | E26: 予備23 | G26: BSS | H26: ビジネスストラテジー推進室 | I26: S1課 | J26: サービス第1課 | K26: EP開3G | L26: EP開発第3グループ | M26: 予備23 | O26: 予備34 | Q26: 予備23 | S26: 予備23 | U26: 予備23 | W26: 予備23 | Y26: 予備23 | AA26: 予備23 | AC26: 予備23 | AE26: 予備23 | AG26: 予備23 | AI26: 予備23 | AK26: 予備23 | AM26: 本部長補佐 | AO26: 予備23 | AQ26: 予備23 | AS26: 363000 | AW26: 120000 | AY26: =MID(BA26,1,1)&" "&MID(BA26,2,1)&" "&MID(BA26,3,LEN(BA26)) | BA26: 3-B | BC26: EE12 | BE26: 700000 | BG26: 930000 | BI26: EE2 | BK26: 1400000 | BM26: =AM26 | BO26: 4000000 | BQ26: 2000000 | BS26: EE12 | CG26: 予備23 | CI26: 予備23 | CK26: 予備23 | CM26: 予備23 | CO26: 予備23 | CQ26: 予備23 | CS26: 予備23 | CU26: 予備23 | CW26: 予備23 | CY26: 予備23 | DA26: 予備23 | DC26: 予備23 | DE26: 予備23 | DG26: 予備23 | DI26: 予備23 | DK26: 予備23 | EA26: 予備23 | EC26: 備品消耗品 | EE26: 諸会費 | EG26: 予備23 | EI26: 予備23 | EY26: 予備23 | FA26: 予備23 | FC26: 予備23 | FE26: 予備23 | FG26: 予備23 | FI26: 予備23 | FK26: 予備23 | FM26: 予備23 | FO26: 予備23 | FQ26: 予備23 | FS26: 予備23 | FU26: 予備23 | FW26: DUE DATE | FY26: 予備23 | GA26: 予備23 | GC26: 予備23 | GE26: 予備23 | GG26: 予備23 | GI26: 予備23 | GK26: 予備23 | GM26: 予備23 | GO26: 予備23 | HE26: 予備23 | HG26: 予備23 | HI26: 予備23 | HK26: 予備23 | HM26: 予備23 | HO26: 予備23 | HQ26: 予備23 | HS26: 予備23 | HU26: 予備23 | HW26: 予備23 | HY26: 予備23 | IA26: 予備23 | IC26: 予備23 | IE26: 予備23 | IG26: 予備23 | II26: 予備23 | IK26: 予備23 | IM26: 予備23 | IO26: 予備23 | IQ26: 予備23 | IS26: 予備23 | IU26: 予備23 | IW26: 予備23 | IY26: 予備23 | JA26: 予備23 | JC26: 予備23
C27: セールスマネージャ | E27: 予備24 | G27: 育成室 | H27: スペシャリスト育成室 | I27: S2課 | J27: サービス第2課 | K27: CS1G | L27: CS第1グループ | M27: 予備24 | O27: 予備35 | Q27: 予備24 | S27: 予備24 | U27: 予備24 | W27: 予備24 | Y27: 予備24 | AA27: 予備24 | AC27: 予備24 | AE27: 予備24 | AG27: 予備24 | AI27: 予備24 | AK27: 予備24 | AM27: 事業部長 | AO27: 予備24 | AQ27: 予備24 | AS27: 354000 | AW27: 120000 | AY27: =MID(BA27,1,1)&" "&MID(BA27,2,1)&" "&MID(BA27,3,LEN(BA27)) | BA27: 3-C | BC27: EE13 | BE27: 650000 | BG27: 900000 | BI27: EE3 | BK27: 1300000 | BM27: =AM27 | BO27: 4000000 | BQ27: 2000000 | BS27: EE13 | CG27: 予備24 | CI27: 予備24 | CK27: 予備24 | CM27: 予備24 | CO27: 予備24 | CQ27: 予備24 | CS27: 予備24 | CU27: 予備24 | CW27: 予備24 | CY27: 予備24 | DA27: 予備24 | DC27: 予備24 | DE27: 予備24 | DG27: 予備24 | DI27: 予備24 | DK27: 予備24 | EA27: 予備24 | EC27: 新聞図書費 | EE27: 車両費 | EG27: 予備24 | EI27: 予備24 | EY27: 予備24 | FA27: 予備24 | FC27: 予備24 | FE27: 予備24 | FG27: 予備24 | FI27: 予備24 | FK27: 予備24 | FM27: 予備24 | FO27: 予備24 | FQ27: 予備24 | FS27: 予備24 | FU27: 予備24 | FW27: 消費税 | FY27: 予備24 | GA27: 予備24 | GC27: 予備24 | GE27: 予備24 | GG27: 予備24 | GI27: 予備24 | GK27: 予備24 | GM27: 予備24 | GO27: 予備24 | HE27: 予備24 | HG27: 予備24 | HI27: 予備24 | HK27: 予備24 | HM27: 予備24 | HO27: 予備24 | HQ27: 予備24 | HS27: 予備24 | HU27: 予備24 | HW27: 予備24 | HY27: 予備24 | IA27: 予備24 | IC27: 予備24 | IE27: 予備24 | IG27: 予備24 | II27: 予備24 | IK27: 予備24 | IM27: 予備24 | IO27: 予備24 | IQ27: 予備24 | IS27: 予備24 | IU27: 予備24 | IW27: 予備24 | IY27: 予備24 | JA27: 予備24 | JC27: 予備24
C28: マーケティングマネージャ | E28: 予備25 | G28: 首都セル部 | H28: 首都圏セールス部 | I28: S3課 | J28: サービス第3課 | K28: CS2G | L28: CS第2グループ | M28: 予備25 | O28: 予備36 | Q28: 予備25 | S28: 予備25 | U28: 予備25 | W28: 予備25 | Y28: 予備25 | AA28: 予備25 | AC28: 予備25 | AE28: 予備25 | AG28: 予備25 | AI28: 予備25 | AK28: 予備25 | AM28: 事業部長代行 | AO28: 予備25 | AQ28: 予備25 | AS28: 345000 | AW28: 120000 | AY28: =MID(BA28,1,1)&" "&MID(BA28,2,1)&" "&MID(BA28,3,LEN(BA28)) | BA28: 3-D | BC28: EE14 | BE28: 600000 | BG28: 880000 | BI28: EE3 | BK28: 1300000 | BM28: =AM28 | BO28: 4000000 | BQ28: 2000000 | BS28: EE14 | CG28: 予備25 | CI28: 予備25 | CK28: 予備25 | CM28: 予備25 | CO28: 予備25 | CQ28: 予備25 | CS28: 予備25 | CU28: 予備25 | CW28: 予備25 | CY28: 予備25 | DA28: 予備25 | DC28: 予備25 | DE28: 予備25 | DG28: 予備25 | DI28: 予備25 | DK28: 予備25 | EA28: 予備25 | EC28: 修繕費 | EE28: 修繕費 | EG28: 予備25 | EI28: 予備25 | EY28: 予備25 | FA28: 予備25 | FC28: 予備25 | FE28: 予備25 | FG28: 予備25 | FI28: 予備25 | FK28: 予備25 | FM28: 予備25 | FO28: 予備25 | FQ28: 予備25 | FS28: 予備25 | FU28: 予備25 | FW28: TAX | FY28: 予備25 | GA28: 予備25 | GC28: 予備25 | GE28: 予備25 | GG28: 予備25 | GI28: 予備25 | GK28: 予備25 | GM28: 予備25 | GO28: 予備25 | HE28: 予備25 | HG28: 予備25 | HI28: 予備25 | HK28: 予備25 | HM28: 予備25 | HO28: 予備25 | HQ28: 予備25 | HS28: 予備25 | HU28: 予備25 | HW28: 予備25 | HY28: 予備25 | IA28: 予備25 | IC28: 予備25 | IE28: 予備25 | IG28: 予備25 | II28: 予備25 | IK28: 予備25 | IM28: 予備25 | IO28: 予備25 | IQ28: 予備25 | IS28: 予備25 | IU28: 予備25 | IW28: 予備25 | IY28: 予備25 | JA28: 予備25 | JC28: 予備25
C29: リージョンマネージャ | E29: 予備26 | G29: 西セル部 | H29: 西日本セールス部 | I29: S4課 | J29: サービス第4課 | K29: AS1G | L29: AS第1グループ | M29: 予備26 | O29: 予備37 | Q29: 予備26 | S29: 予備26 | U29: 予備26 | W29: 予備26 | Y29: 予備26 | AA29: 予備26 | AC29: 予備26 | AE29: 予備26 | AG29: 予備26 | AI29: 予備26 | AK29: 予備26 | AM29: 事業部長補佐 | AO29: 予備26 | AQ29: 予備26 | AS29: 336000 | AW29: 120000 | AY29: =MID(BA29,1,1)&" "&MID(BA29,2,1)&" "&MID(BA29,3,LEN(BA29)) | BA29: 3-E | BC29: EE15 | BE29: 580000 | BG29: 850000 | BI29: EE4 | BK29: 1200000 | BM29: =AM29 | BO29: 4000000 | BQ29: 2000000 | BS29: EE15 | CG29: 予備26 | CI29: 予備26 | CK29: 予備26 | CM29: 予備26 | CO29: 予備26 | CQ29: 予備26 | CS29: 予備26 | CU29: 予備26 | CW29: 予備26 | CY29: 予備26 | DA29: 予備26 | DC29: 予備26 | DE29: 予備26 | DG29: 予備26 | DI29: 予備26 | DK29: 予備26 | EA29: 予備26 | EC29: 地代家賃 | EE29: 地代家賃 | EG29: 予備26 | EI29: 予備26 | EY29: 予備26 | FA29: 予備26 | FC29: 予備26 | FE29: 予備26 | FG29: 予備26 | FI29: 予備26 | FK29: 予備26 | FM29: 予備26 | FO29: 予備26 | FQ29: 予備26 | FS29: 予備26 | FU29: 予備26 | FW29: 件名 | FY29: 予備26 | GA29: 予備26 | GC29: 予備26 | GE29: 予備26 | GG29: 予備26 | GI29: 予備26 | GK29: 予備26 | GM29: 予備26 | GO29: 予備26 | HE29: 予備26 | HG29: 予備26 | HI29: 予備26 | HK29: 予備26 | HM29: 予備26 | HO29: 予備26 | HQ29: 予備26 | HS29: 予備26 | HU29: 予備26 | HW29: 予備26 | HY29: 予備26 | IA29: 予備26 | IC29: 予備26 | IE29: 予備26 | IG29: 予備26 | II29: 予備26 | IK29: 予備26 | IM29: 予備26 | IO29: 予備26 | IQ29: 予備26 | IS29: 予備26 | IU29: 予備26 | IW29: 予備26 | IY29: 予備26 | JA29: 予備26 | JC29: 予備26
C30: 統括マネージャ | E30: 予備27 | G30: T&S部 | H30: テクノロジー＆サイエンス部 | I30: S5課 | J30: サービス第5課 | K30: AS2G | L30: AS第2グループ | M30: 予備27 | O30: 予備38 | Q30: 予備27 | S30: 予備27 | U30: 予備27 | W30: 予備27 | Y30: 予備27 | AA30: 予備27 | AC30: 予備27 | AE30: 予備27 | AG30: 予備27 | AI30: 予備27 | AK30: 予備27 | AM30: 統括部長 | AO30: 予備27 | AQ30: 予備27 | AS30: 327000 | AW30: 120000 | AY30: =MID(BA30,1,1)&" "&MID(BA30,2,1)&" "&MID(BA30,3,LEN(BA30)) | BA30: 3-F | BC30: EE16 | BE30: 550000 | BG30: 830000 | BI30: EE4 | BK30: 1200000 | BM30: =AM30 | BO30: 1500000 | BQ30: 1500000 | BS30: EE16 | CG30: 予備27 | CI30: 予備27 | CK30: 予備27 | CM30: 予備27 | CO30: 予備27 | CQ30: 予備27 | CS30: 予備27 | CU30: 予備27 | CW30: 予備27 | CY30: 予備27 | DA30: 予備27 | DC30: 予備27 | DE30: 予備27 | DG30: 予備27 | DI30: 予備27 | DK30: 予備27 | EA30: 予備27 | EC30: 車両燃料費 | EE30: 販売手数料 | EG30: 予備27 | EI30: 予備27 | EY30: 予備27 | FA30: 予備27 | FC30: 予備27 | FE30: 予備27 | FG30: 予備27 | FI30: 予備27 | FK30: 予備27 | FM30: 予備27 | FO30: 予備27 | FQ30: 予備27 | FS30: 予備27 | FU30: 予備27 | FW30: PROJECT NAME | FY30: 予備27 | GA30: 予備27 | GC30: 予備27 | GE30: 予備27 | GG30: 予備27 | GI30: 予備27 | GK30: 予備27 | GM30: 予備27 | GO30: 予備27 | HE30: 予備27 | HG30: 予備27 | HI30: 予備27 | HK30: 予備27 | HM30: 予備27 | HO30: 予備27 | HQ30: 予備27 | HS30: 予備27 | HU30: 予備27 | HW30: 予備27 | HY30: 予備27 | IA30: 予備27 | IC30: 予備27 | IE30: 予備27 | IG30: 予備27 | II30: 予備27 | IK30: 予備27 | IM30: 予備27 | IO30: 予備27 | IQ30: 予備27 | IS30: 予備27 | IU30: 予備27 | IW30: 予備27 | IY30: 予備27 | JA30: 予備27 | JC30: 予備27
C31: ゼネラルマネージャ | E31: 予備28 | G31: NBS部 | H31: ネットビジネスサービス部 | I31: SI1課 | J31: SIサービス第1課 | K31: AS3G | L31: AS第3グループ | M31: 予備28 | O31: 予備39 | Q31: 予備28 | S31: 予備28 | U31: 予備28 | W31: 予備28 | Y31: 予備28 | AA31: 予備28 | AC31: 予備28 | AE31: 予備28 | AG31: 予備28 | AI31: 予備28 | AK31: 予備28 | AM31: 統括部長代行 | AO31: 予備28 | AQ31: 予備28 | AS31: 318000 | AW31: 115000 | AY31: =MID(BA31,1,1)&" "&MID(BA31,2,1)&" "&MID(BA31,3,LEN(BA31)) | BA31: 3-G | BC31: EE17 | BE31: 500000 | BG31: 800000 | BI31: EE5 | BK31: 1100000 | BM31: =AM31 | BO31: 1500000 | BQ31: 1500000 | BS31: EE17 | CG31: 予備28 | CI31: 予備28 | CK31: 予備28 | CM31: 予備28 | CO31: 予備28 | CQ31: 予備28 | CS31: 予備28 | CU31: 予備28 | CW31: 予備28 | CY31: 予備28 | DA31: 予備28 | DC31: 予備28 | DE31: 予備28 | DG31: 予備28 | DI31: 予備28 | DK31: 予備28 | EA31: 予備28 | EC31: 車両維持費 | EE31: 支払手数料 | EG31: 予備28 | EI31: 予備28 | EY31: 予備28 | FA31: 予備28 | FC31: 予備28 | FE31: 予備28 | FG31: 予備28 | FI31: 予備28 | FK31: 予備28 | FM31: 予備28 | FO31: 予備28 | FQ31: 予備28 | FS31: 予備28 | FU31: 予備28 | FW31: 契約期間 | FY31: 予備28 | GA31: 予備28 | GC31: 予備28 | GE31: 予備28 | GG31: 予備28 | GI31: 予備28 | GK31: 予備28 | GM31: 予備28 | GO31: 予備28 | HE31: 予備28 | HG31: 予備28 | HI31: 予備28 | HK31: 予備28 | HM31: 予備28 | HO31: 予備28 | HQ31: 予備28 | HS31: 予備28 | HU31: 予備28 | HW31: 予備28 | HY31: 予備28 | IA31: 予備28 | IC31: 予備28 | IE31: 予備28 | IG31: 予備28 | II31: 予備28 | IK31: 予備28 | IM31: 予備28 | IO31: 予備28 | IQ31: 予備28 | IS31: 予備28 | IU31: 予備28 | IW31: 予備28 | IY31: 予備28 | JA31: 予備28 | JC31: 予備28
C32: マネージャ | E32: 予備29 | G32: PJS部 | H32: プロジェクトサービス部 | I32: SI2課 | J32: SIサービス第2課 | K32: AS4G | L32: AS第4グループ | M32: 予備29 | O32: 予備40 | Q32: 予備29 | S32: 予備29 | U32: 予備29 | W32: 予備29 | Y32: 予備29 | AA32: 予備29 | AC32: 予備29 | AE32: 予備29 | AG32: 予備29 | AI32: 予備29 | AK32: 予備29 | AM32: 統括部長補佐 | AO32: 予備29 | AQ32: 予備29 | AS32: 309000 | AW32: 115000 | AY32: =MID(BA32,1,1)&" "&MID(BA32,2,1)&" "&MID(BA32,3,LEN(BA32)) | BA32: 3-H | BC32: EE18 | BE32: 450000 | BG32: 780000 | BI32: EE5 | BK32: 1100000 | BM32: =AM32 | BO32: 1400000 | BQ32: 1400000 | BS32: EE18 | CG32: 予備29 | CI32: 予備29 | CK32: 予備29 | CM32: 予備29 | CO32: 予備29 | CQ32: 予備29 | CS32: 予備29 | CU32: 予備29 | CW32: 予備29 | CY32: 予備29 | DA32: 予備29 | DC32: 予備29 | DE32: 予備29 | DG32: 予備29 | DI32: 予備29 | DK32: 予備29 | EA32: 予備29 | EC32: 保険料 | EE32: 保険料 | EG32: 予備29 | EI32: 予備29 | EY32: 予備29 | FA32: 予備29 | FC32: 予備29 | FE32: 予備29 | FG32: 予備29 | FI32: 予備29 | FK32: 予備29 | FM32: 予備29 | FO32: 予備29 | FQ32: 予備29 | FS32: 予備29 | FU32: 予備29 | FW32: CONTRACT TERM | FY32: 予備29 | GA32: 予備29 | GC32: 予備29 | GE32: 予備29 | GG32: 予備29 | GI32: 予備29 | GK32: 予備29 | GM32: 予備29 | GO32: 予備29 | HE32: 予備29 | HG32: 予備29 | HI32: 予備29 | HK32: 予備29 | HM32: 予備29 | HO32: 予備29 | HQ32: 予備29 | HS32: 予備29 | HU32: 予備29 | HW32: 予備29 | HY32: 予備29 | IA32: 予備29 | IC32: 予備29 | IE32: 予備29 | IG32: 予備29 | II32: 予備29 | IK32: 予備29 | IM32: 予備29 | IO32: 予備29 | IQ32: 予備29 | IS32: 予備29 | IU32: 予備29 | IW32: 予備29 | IY32: 予備29 | JA32: 予備29 | JC32: 予備29
C33: アシスタントマネージャ | E33: 予備30 | G33: CSI部 | H33: クラウドSI部 | I33: 西技課 | J33: 西日本クラウド技術課 | K33: BEX1G | L33: BEX第1グループ | M33: 予備30 | O33: 予備41 | Q33: 予備30 | S33: 予備30 | U33: 予備30 | W33: 予備30 | Y33: 予備30 | AA33: 予備30 | AC33: 予備30 | AE33: 予備30 | AG33: 予備30 | AI33: 予備30 | AK33: 予備30 | AM33: ユニット長 | AO33: 予備30 | AQ33: 予備30 | AS33: 300000 | AW33: 115000 | AY33: =MID(BA33,1,1)&" "&MID(BA33,2,1)&" "&MID(BA33,3,LEN(BA33)) | BA33: 3-I | BC33: 予備30 | BE33: 予備30 | BG33: 750000 | BI33: EE5 | BK33: 1100000 | BM33: =AM33 | BO33: 1500000 | BQ33: 1500000 | BS33: 予備30 | CG33: 予備30 | CI33: 予備30 | CK33: 予備30 | CM33: 予備30 | CO33: 予備30 | CQ33: 予備30 | CS33: 予備30 | CU33: 予備30 | CW33: 予備30 | CY33: 予備30 | DA33: 予備30 | DC33: 予備30 | DE33: 予備30 | DG33: 予備30 | DI33: 予備30 | DK33: 予備30 | EA33: 予備30 | EC33: 租税公課 | EE33: 租税・印紙 | EG33: 予備30 | EI33: 予備30 | EY33: 予備30 | FA33: 予備30 | FC33: 予備30 | FE33: 予備30 | FG33: 予備30 | FI33: 予備30 | FK33: 予備30 | FM33: 予備30 | FO33: 予備30 | FQ33: 予備30 | FS33: 予備30 | FU33: 予備30 | FW33: 納入期限 | FY33: 予備30 | GA33: 予備30 | GC33: 予備30 | GE33: 予備30 | GG33: 予備30 | GI33: 予備30 | GK33: 予備30 | GM33: 予備30 | GO33: 予備30 | HE33: 予備30 | HG33: 予備30 | HI33: 予備30 | HK33: 予備30 | HM33: 予備30 | HO33: 予備30 | HQ33: 予備30 | HS33: 予備30 | HU33: 予備30 | HW33: 予備30 | HY33: 予備30 | IA33: 予備30 | IC33: 予備30 | IE33: 予備30 | IG33: 予備30 | II33: 予備30 | IK33: 予備30 | IM33: 予備30 | IO33: 予備30 | IQ33: 予備30 | IS33: 予備30 | IU33: 予備30 | IW33: 予備30 | IY33: 予備30 | JA33: 予備30 | JC33: 予備30
E34: 予備31 | G34: UCN部 | H34: UCネットワーク部 | I34: 西開課 | J34: 西日本システム開発課 | K34: BEX2G | L34: BEX第2グループ | M34: 予備31 | O34: 予備42 | Q34: 予備31 | S34: 予備31 | U34: 予備31 | W34: 予備31 | Y34: 予備31 | AA34: 予備31 | AC34: 予備31 | AE34: 予備31 | AG34: 予備31 | AI34: 予備31 | AK34: 予備31 | AM34: ユニット長代行 | AO34: 予備31 | AQ34: 予備31 | AS34: 291000 | AW34: 115000 | AY34: =MID(BA34,1,1)&" "&MID(BA34,2,1)&" "&MID(BA34,3,LEN(BA34)) | BA34: 3-J | BC34: 予備31 | BE34: 予備31 | BG34: 730000 | BI34: EE5 | BK34: 1100000 | BM34: =AM34 | BO34: 1400000 | BQ34: 1400000 | BS34: 予備31 | CG34: 予備31 | CI34: 予備31 | CK34: 予備31 | CM34: 予備31 | CO34: 予備31 | CQ34: 予備31 | CS34: 予備31 | CU34: 予備31 | CW34: 予備31 | CY34: 予備31 | DA34: 予備31 | DC34: 予備31 | DE34: 予備31 | DG34: 予備31 | DI34: 予備31 | DK34: 予備31 | EA34: 予備31 | EC34: 諸会費 | EE34: 雑費 | EG34: 予備31 | EI34: 予備31 | EY34: 予備31 | FA34: 予備31 | FC34: 予備31 | FE34: 予備31 | FG34: 予備31 | FI34: 予備31 | FK34: 予備31 | FM34: 予備31 | FO34: 予備31 | FQ34: 予備31 | FS34: 予備31 | FU34: 予備31 | FW34: DELIVERY DATE | FY34: 予備31 | GA34: 予備31 | GC34: 予備31 | GE34: 予備31 | GG34: 予備31 | GI34: 予備31 | GK34: 予備31 | GM34: 予備31 | GO34: 予備31 | HE34: 予備31 | HG34: 予備31 | HI34: 予備31 | HK34: 予備31 | HM34: 予備31 | HO34: 予備31 | HQ34: 予備31 | HS34: 予備31 | HU34: 予備31 | HW34: 予備31 | HY34: 予備31 | IA34: 予備31 | IC34: 予備31 | IE34: 予備31 | IG34: 予備31 | II34: 予備31 | IK34: 予備31 | IM34: 予備31 | IO34: 予備31 | IQ34: 予備31 | IS34: 予備31 | IU34: 予備31 | IW34: 予備31 | IY34: 予備31 | JA34: 予備31 | JC34: 予備31
C35: シニアデザイナー Senior Designer | E35: 予備32 | G35: 社長室 | H35: 社長室（代表付） | I35: PJ1課 | J35: プロジェクトサービス第1課 | K35: UC1G | L35: UC技術第1グループ | M35: 予備32 | O35: 予備43 | Q35: 予備32 | S35: 予備32 | U35: 予備32 | W35: 予備32 | Y35: 予備32 | AA35: 予備32 | AC35: 予備32 | AE35: 予備32 | AG35: 予備32 | AI35: 予備32 | AK35: 予備32 | AM35: ユニット長補佐 | AO35: 予備32 | AQ35: 予備32 | AS35: 327000 | AW35: 100000 | AY35: =MID(BA35,1,1)&" "&MID(BA35,2,1)&" "&MID(BA35,3,LEN(BA35)) | BA35: 4-A | BC35: 予備32 | BE35: 予備32 | BG35: 700000 | BI35: EE6 | BK35: 1000000 | BM35: =AM35 | BO35: 1400000 | BQ35: 1400000 | BS35: 予備32 | CG35: 予備32 | CI35: 予備32 | CK35: 予備32 | CM35: 予備32 | CO35: 予備32 | CQ35: 予備32 | CS35: 予備32 | CU35: 予備32 | CW35: 予備32 | CY35: 予備32 | DA35: 予備32 | DC35: 予備32 | DE35: 予備32 | DG35: 予備32 | DI35: 予備32 | DK35: 予備32 | EA35: 予備32 | EC35: リース料 | EE35: 非税その他 ※原則使用しない | EG35: 予備32 | EI35: 予備32 | EY35: 予備32 | FA35: 予備32 | FC35: 予備32 | FE35: 予備32 | FG35: 予備32 | FI35: 予備32 | FK35: 予備32 | FM35: 予備32 | FO35: 予備32 | FQ35: 予備32 | FS35: 予備32 | FU35: 予備32 | FW35: 納入場所 | FY35: 予備32 | GA35: 予備32 | GC35: 予備32 | GE35: 予備32 | GG35: 予備32 | GI35: 予備32 | GK35: 予備32 | GM35: 予備32 | GO35: 予備32 | HE35: 予備32 | HG35: 予備32 | HI35: 予備32 | HK35: 予備32 | HM35: 予備32 | HO35: 予備32 | HQ35: 予備32 | HS35: 予備32 | HU35: 予備32 | HW35: 予備32 | HY35: 予備32 | IA35: 予備32 | IC35: 予備32 | IE35: 予備32 | IG35: 予備32 | II35: 予備32 | IK35: 予備32 | IM35: 予備32 | IO35: 予備32 | IQ35: 予備32 | IS35: 予備32 | IU35: 予備32 | IW35: 予備32 | IY35: 予備32 | JA35: 予備32 | JC35: 予備32
C36: デザイナー Designer | E36: 予備33 | G36: ｿﾘ営1部 | H36: ソリューション営業第1部 | I36: PJ2課 | J36: プロジェクトサービス第2課 | K36: UC2G | L36: UC技術第2グループ | M36: 予備33 | O36: 予備44 | Q36: 予備33 | S36: 予備33 | U36: 予備33 | W36: 予備33 | Y36: 予備33 | AA36: 予備33 | AC36: 予備33 | AE36: 予備33 | AG36: 予備33 | AI36: 予備33 | AK36: 予備33 | AM36: 部長 | AO36: 予備33 | AQ36: 予備33 | AS36: 319000 | AW36: 100000 | AY36: =MID(BA36,1,1)&" "&MID(BA36,2,1)&" "&MID(BA36,3,LEN(BA36)) | BA36: 4-B | BC36: 予備33 | BE36: 予備33 | BG36: 680000 | BI36: EE6 | BK36: 1000000 | BM36: =AM36 | BO36: 1300000 | BQ36: 1300000 | BS36: 予備33 | CG36: 予備33 | CI36: 予備33 | CK36: 予備33 | CM36: 予備33 | CO36: 予備33 | CQ36: 予備33 | CS36: 予備33 | CU36: 予備33 | CW36: 予備33 | CY36: 予備33 | DA36: 予備33 | DC36: 予備33 | DE36: 予備33 | DG36: 予備33 | DI36: 予備33 | DK36: 予備33 | EA36: 予備33 | EC36: 支払手数料 | EE36: 課税その他 ※原則使用しない | EG36: 予備33 | EI36: 予備33 | EY36: 予備33 | FA36: 予備33 | FC36: 予備33 | FE36: 予備33 | FG36: 予備33 | FI36: 予備33 | FK36: 予備33 | FM36: 予備33 | FO36: 予備33 | FQ36: 予備33 | FS36: 予備33 | FU36: 予備33 | FW36: DELIVERY POINT | FY36: 予備33 | GA36: 予備33 | GC36: 予備33 | GE36: 予備33 | GG36: 予備33 | GI36: 予備33 | GK36: 予備33 | GM36: 予備33 | GO36: 予備33 | HE36: 予備33 | HG36: 予備33 | HI36: 予備33 | HK36: 予備33 | HM36: 予備33 | HO36: 予備33 | HQ36: 予備33 | HS36: 予備33 | HU36: 予備33 | HW36: 予備33 | HY36: 予備33 | IA36: 予備33 | IC36: 予備33 | IE36: 予備33 | IG36: 予備33 | II36: 予備33 | IK36: 予備33 | IM36: 予備33 | IO36: 予備33 | IQ36: 予備33 | IS36: 予備33 | IU36: 予備33 | IW36: 予備33 | IY36: 予備33 | JA36: 予備33 | JC36: 予備33
E37: 予備34 | G37: ｿﾘ営2部 | H37: ソリューション営業第2部 | I37: ｸﾗﾋﾞｼﾞ1課 | J37: クラウドビジネス第1課 | K37: UC3G | L37: UC技術第3グループ | M37: 予備34 | O37: 予備45 | Q37: 予備34 | S37: 予備34 | U37: 予備34 | W37: 予備34 | Y37: 予備34 | AA37: 予備34 | AC37: 予備34 | AE37: 予備34 | AG37: 予備34 | AI37: 予備34 | AK37: 予備34 | AM37: 担当部長（プロジェクト部長） | AO37: 予備34 | AQ37: 予備34 | AS37: 311000 | AW37: 100000 | AY37: =MID(BA37,1,1)&" "&MID(BA37,2,1)&" "&MID(BA37,3,LEN(BA37)) | BA37: 4-C | BC37: 予備34 | BE37: 予備34 | BG37: 650000 | BI37: EE7 | BK37: 950000 | BM37: =AM37 | BO37: 1200000 | BQ37: 1200000 | BS37: 予備34 | CG37: 予備34 | CI37: 予備34 | CK37: 予備34 | CM37: 予備34 | CO37: 予備34 | CQ37: 予備34 | CS37: 予備34 | CU37: 予備34 | CW37: 予備34 | CY37: 予備34 | DA37: 予備34 | DC37: 予備34 | DE37: 予備34 | DG37: 予備34 | DI37: 予備34 | DK37: 予備34 | EA37: 予備34 | EC37: 外注費（販） | EE37: 予備45 | EG37: 予備34 | EI37: 予備34 | EY37: 予備34 | FA37: 予備34 | FC37: 予備34 | FE37: 予備34 | FG37: 予備34 | FI37: 予備34 | FK37: 予備34 | FM37: 予備34 | FO37: 予備34 | FQ37: 予備34 | FS37: 予備34 | FU37: 予備34 | FW37: 支払条件 | FY37: 予備34 | GA37: 予備34 | GC37: 予備34 | GE37: 予備34 | GG37: 予備34 | GI37: 予備34 | GK37: 予備34 | GM37: 予備34 | GO37: 予備34 | HE37: 予備34 | HG37: 予備34 | HI37: 予備34 | HK37: 予備34 | HM37: 予備34 | HO37: 予備34 | HQ37: 予備34 | HS37: 予備34 | HU37: 予備34 | HW37: 予備34 | HY37: 予備34 | IA37: 予備34 | IC37: 予備34 | IE37: 予備34 | IG37: 予備34 | II37: 予備34 | IK37: 予備34 | IM37: 予備34 | IO37: 予備34 | IQ37: 予備34 | IS37: 予備34 | IU37: 予備34 | IW37: 予備34 | IY37: 予備34 | JA37: 予備34 | JC37: 予備34
C38: シニアディレクター Senior Director | E38: 予備35 | G38: ｿﾘ営3部 | H38: ソリューション営業第3部 | I38: IT課 | J38: ITサービスマネジメント課 | K38: UC4G | L38: UC技術第4グループ | M38: 予備35 | O38: 予備45 | Q38: 予備35 | S38: 予備35 | U38: 予備35 | W38: 予備35 | Y38: 予備35 | AA38: 予備35 | AC38: 予備35 | AE38: 予備35 | AG38: 予備35 | AI38: 予備35 | AK38: 予備35 | AM38: 部長代行 | AO38: 予備35 | AQ38: 予備35 | AS38: 303000 | AW38: 100000 | AY38: =MID(BA38,1,1)&" "&MID(BA38,2,1)&" "&MID(BA38,3,LEN(BA38)) | BA38: 4-D | BC38: 予備35 | BE38: 予備35 | BG38: 630000 | BI38: EE8 | BK38: 900000 | BM38: =AM38 | BO38: 1200000 | BQ38: 1200000 | BS38: 予備35 | CG38: 予備35 | CI38: 予備35 | CK38: 予備35 | CM38: 予備35 | CO38: 予備35 | CQ38: 予備35 | CS38: 予備35 | CU38: 予備35 | CW38: 予備35 | CY38: 予備35 | DA38: 予備35 | DC38: 予備35 | DE38: 予備35 | DG38: 予備35 | DI38: 予備35 | DK38: 予備35 | EA38: 予備35 | EC38: 販売手数料 | EE38: 予備45 | EG38: 予備35 | EI38: 予備35 | EY38: 予備35 | FA38: 予備35 | FC38: 予備35 | FE38: 予備35 | FG38: 予備35 | FI38: 予備35 | FK38: 予備35 | FM38: 予備35 | FO38: 予備35 | FQ38: 予備35 | FS38: 予備35 | FU38: 予備35 | FW38: DUE DATE | FY38: 予備35 | GA38: 予備35 | GC38: 予備35 | GE38: 予備35 | GG38: 予備35 | GI38: 予備35 | GK38: 予備35 | GM38: 予備35 | GO38: 予備35 | HE38: 予備35 | HG38: 予備35 | HI38: 予備35 | HK38: 予備35 | HM38: 予備35 | HO38: 予備35 | HQ38: 予備35 | HS38: 予備35 | HU38: 予備35 | HW38: 予備35 | HY38: 予備35 | IA38: 予備35 | IC38: 予備35 | IE38: 予備35 | IG38: 予備35 | II38: 予備35 | IK38: 予備35 | IM38: 予備35 | IO38: 予備35 | IQ38: 予備35 | IS38: 予備35 | IU38: 予備35 | IW38: 予備35 | IY38: 予備35 | JA38: 予備35 | JC38: 予備35
C39: ディレクター Director | E39: 予備36 | G39: 営推部 | H39: 営業推進部 | I39: 西セル課 | J39: 西日本セールス課 | K39: NW1G | L39: ネットワーク技術第1グループ | M39: 予備36 | O39: 予備45 | Q39: 予備36 | S39: 予備36 | U39: 予備36 | W39: 予備36 | Y39: 予備36 | AA39: 予備36 | AC39: 予備36 | AE39: 予備36 | AG39: 予備36 | AI39: 予備36 | AK39: 予備36 | AM39: 部長補佐 | AO39: 予備36 | AQ39: 予備36 | AS39: 295000 | AW39: 100000 | AY39: =MID(BA39,1,1)&" "&MID(BA39,2,1)&" "&MID(BA39,3,LEN(BA39)) | BA39: 4-E | BC39: 予備36 | BE39: 予備36 | BG39: 600000 | BI39: EE9 | BK39: 850000 | BM39: =AM39 | BO39: 1200000 | BQ39: 1200000 | BS39: 予備36 | CG39: 予備36 | CI39: 予備36 | CK39: 予備36 | CM39: 予備36 | CO39: 予備36 | CQ39: 予備36 | CS39: 予備36 | CU39: 予備36 | CW39: 予備36 | CY39: 予備36 | DA39: 予備36 | DC39: 予備36 | DE39: 予備36 | DG39: 予備36 | DI39: 予備36 | DK39: 予備36 | EA39: 予備36 | EC39: 支払報酬料 | EE39: 予備45 | EG39: 予備36 | EI39: 予備36 | EY39: 予備36 | FA39: 予備36 | FC39: 予備36 | FE39: 予備36 | FG39: 予備36 | FI39: 予備36 | FK39: 予備36 | FM39: 予備36 | FO39: 予備36 | FQ39: 予備36 | FS39: 予備36 | FU39: 予備36 | FW39: 金額 | FY39: 予備36 | GA39: 予備36 | GC39: 予備36 | GE39: 予備36 | GG39: 予備36 | GI39: 予備36 | GK39: 予備36 | GM39: 予備36 | GO39: 予備36 | HE39: 予備36 | HG39: 予備36 | HI39: 予備36 | HK39: 予備36 | HM39: 予備36 | HO39: 予備36 | HQ39: 予備36 | HS39: 予備36 | HU39: 予備36 | HW39: 予備36 | HY39: 予備36 | IA39: 予備36 | IC39: 予備36 | IE39: 予備36 | IG39: 予備36 | II39: 予備36 | IK39: 予備36 | IM39: 予備36 | IO39: 予備36 | IQ39: 予備36 | IS39: 予備36 | IU39: 予備36 | IW39: 予備36 | IY39: 予備36 | JA39: 予備36 | JC39: 予備36
E40: 予備37 | G40: PRS営業部 | I40: PJ3課 | J40: プロジェクトサービス第3課 | K40: NW2G | L40: ネットワーク技術第2グループ | M40: 予備37 | O40: 予備45 | Q40: 予備37 | S40: 予備37 | U40: 予備37 | W40: 予備37 | Y40: 予備37 | AA40: 予備37 | AC40: 予備37 | AE40: 予備37 | AG40: 予備37 | AI40: 予備37 | AK40: 予備37 | AM40: 室長 | AO40: 予備37 | AQ40: 予備37 | AS40: 287000 | AW40: 100000 | AY40: =MID(BA40,1,1)&" "&MID(BA40,2,1)&" "&MID(BA40,3,LEN(BA40)) | BA40: 4-F | BC40: 予備37 | BE40: 予備37 | BG40: 580000 | BI40: EE9 | BK40: 850000 | BM40: =AM40 | BO40: 1300000 | BQ40: 1300000 | BS40: 予備37 | CG40: 予備37 | CI40: 予備37 | CK40: 予備37 | CM40: 予備37 | CO40: 予備37 | CQ40: 予備37 | CS40: 予備37 | CU40: 予備37 | CW40: 予備37 | CY40: 予備37 | DA40: 予備37 | DC40: 予備37 | DE40: 予備37 | DG40: 予備37 | DI40: 予備37 | DK40: 予備37 | EA40: 予備37 | EC40: 減価償却費 | EE40: 予備45 | EG40: 予備37 | EI40: 予備37 | EY40: 予備37 | FA40: 予備37 | FC40: 予備37 | FE40: 予備37 | FG40: 予備37 | FI40: 予備37 | FK40: 予備37 | FM40: 予備37 | FO40: 予備37 | FQ40: 予備37 | FS40: 予備37 | FU40: 予備37 | FW40: TOTAL AMOUNT | FY40: 予備37 | GA40: 予備37 | GC40: 予備37 | GE40: 予備37 | GG40: 予備37 | GI40: 予備37 | GK40: 予備37 | GM40: 予備37 | GO40: 予備37 | HE40: 予備37 | HG40: 予備37 | HI40: 予備37 | HK40: 予備37 | HM40: 予備37 | HO40: 予備37 | HQ40: 予備37 | HS40: 予備37 | HU40: 予備37 | HW40: 予備37 | HY40: 予備37 | IA40: 予備37 | IC40: 予備37 | IE40: 予備37 | IG40: 予備37 | II40: 予備37 | IK40: 予備37 | IM40: 予備37 | IO40: 予備37 | IQ40: 予備37 | IS40: 予備37 | IU40: 予備37 | IW40: 予備37 | IY40: 予備37 | JA40: 予備37 | JC40: 予備37
C41: シニアアートディレクター Senior Art Director | E41: 予備38 | G41: BIS部 | H41: ビジネスイノベーションサービス部 | I41: 西営課 | J41: 西日本営業課 | K41: NW3G | L41: ネットワーク技術第3グループ | M41: 予備38 | O41: 予備45 | Q41: 予備38 | S41: 予備38 | U41: 予備38 | W41: 予備38 | Y41: 予備38 | AA41: 予備38 | AC41: 予備38 | AE41: 予備38 | AG41: 予備38 | AI41: 予備38 | AK41: 予備38 | AM41: 室長代行 | AO41: 予備38 | AQ41: 予備38 | AS41: 279000 | AW41: 80000 | AY41: =MID(BA41,1,1)&" "&MID(BA41,2,1)&" "&MID(BA41,3,LEN(BA41)) | BA41: 4-G | BC41: 予備38 | BE41: 予備38 | BG41: 550000 | BI41: EE10 | BK41: 800000 | BM41: =AM41 | BO41: 1200000 | BQ41: 1200000 | BS41: 予備38 | CG41: 予備38 | CI41: 予備38 | CK41: 予備38 | CM41: 予備38 | CO41: 予備38 | CQ41: 予備38 | CS41: 予備38 | CU41: 予備38 | CW41: 予備38 | CY41: 予備38 | DA41: 予備38 | DC41: 予備38 | DE41: 予備38 | DG41: 予備38 | DI41: 予備38 | DK41: 予備38 | EA41: 予備38 | EC41: 長期前払費用償却 | EE41: 予備45 | EG41: 予備38 | EI41: 予備38 | EY41: 予備38 | FA41: 予備38 | FC41: 予備38 | FE41: 予備38 | FG41: 予備38 | FI41: 予備38 | FK41: 予備38 | FM41: 予備38 | FO41: 予備38 | FQ41: 予備38 | FS41: 予備38 | FU41: 予備38 | FW41: 見積詳細 | FY41: 予備38 | GA41: 予備38 | GC41: 予備38 | GE41: 予備38 | GG41: 予備38 | GI41: 予備38 | GK41: 予備38 | GM41: 予備38 | GO41: 予備38 | HE41: 予備38 | HG41: 予備38 | HI41: 予備38 | HK41: 予備38 | HM41: 予備38 | HO41: 予備38 | HQ41: 予備38 | HS41: 予備38 | HU41: 予備38 | HW41: 予備38 | HY41: 予備38 | IA41: 予備38 | IC41: 予備38 | IE41: 予備38 | IG41: 予備38 | II41: 予備38 | IK41: 予備38 | IM41: 予備38 | IO41: 予備38 | IQ41: 予備38 | IS41: 予備38 | IU41: 予備38 | IW41: 予備38 | IY41: 予備38 | JA41: 予備38 | JC41: 予備38
...

Sheet 注文書
B2: 会社名
B3: 代表者表示
B4: 所在地表示 | AJ4: =IF(H2="","", IF(H5="","", IF(H8="","", H8))) | AS4: =IF(H2="","", IF(H5="","", IF(H5=固定マスタ!DG5,"", IF(AND(H5=固定マスタ!DG6,H8=固定マスタ!FA5),固定マスタ!GI5, IF(AND(H5=固定マスタ!DG6,H8=固定マスタ!FA6),固定マスタ!GI5, IF(AND(H5=固定マスタ!DG6,H8=固定マスタ!FA7),固定マスタ!GI6, IF(AND(H5=固定マスタ!DG6,H8=固定マスタ!FA8),固定マスタ!GI6, IF(AND(H5=固定マスタ!DG6,H8=固定マスタ!FA9),"", IF(AND(H5=固定マスタ!DG6,H8=固定マスタ!FA10),"", IF(AND(H5=固定マスタ!DG6,H8=固定マスタ!FA11),"", IF(AND(H5=固定マスタ!DG6,H8=固定マスタ!FA12),"", IF(AND(H5=固定マスタ!DG6,H8=固定マスタ!FA13),"", "error"))))))))))))
B5: 商流
B6: 個別管理番号 | AR6: =IF(H2="","", IF(H8="","", IF(H8=固定マスタ!FA5,固定マスタ!FS5, IF(H8=固定マスタ!FA6,固定マスタ!FS5, IF(H8=固定マスタ!FA7,固定マスタ!FS6, IF(H8=固定マスタ!FA8,固定マスタ!FS6, IF(H8=固定マスタ!FA9,"", IF(H8=固定マスタ!FA10,"", IF(H8=固定マスタ!FA11,"", IF(H8=固定マスタ!FA12,"", IF(H8=固定マスタ!FA13,"", "error"))))))))))) | AS6: =IF(H2="","", IF(H8="","", IF(H6="","",H6)))
B7: 契約書日付 | L7: 年 | P7: 月 | T7: 日
